Workbook

Sheet LEIA-ME
A1: MODELO DE CONTROLE COMERCIAL + LOGÍSTICO
A2: Transporte fracionado de veículos — v2 (regras confirmadas com o cliente)
A4: COMO LER | B4: Azul = campo digitado. Preto = calculado por fórmula (não digitar). Amarelo = parâmetro.
A6: REGRA DE OURO | B6: O veículo (chassi) é a unidade de tudo: frete, status, seguro, checklist, ocorrência, CT-e e rateio. A carga é só o agrupamento de veículos que um executante levou em um pedaço do caminho.
A8: 1. RATEIO DA RECEITA | B8: POR KM. O peso de cada trecho = km do trecho ÷ km total do veículo. A soma dos trechos de um veículo tem que fechar 100% (coluna CHECK_RATEIO acusa).
B9: Para dividir de outra forma em um caso específico, digite em PESO_MANUAL na aba TRECHOS.
A11: 2. BASE DE REMUNERAÇÃO | B11: FRETE MENOS CUSTO. A base do executante = receita do trecho − custos dedutíveis daquele trecho.
B12: Custo de nível CARGA (pedágio, combustível) é rateado entre os veículos da carga na proporção da receita.
B13: Custo de nível TRECHO (adiantamento, estadia) é lançado direto no veículo.
B14: DEDUZ_BASE = SIM → o custo desconta do executante. NAO → é custo da empresa, entra só na margem.
B15: Regra %_FRETE: recebe % sobre a base líquida. Regras R$/KM e FIXO_VEICULO: valor cheio menos os custos dedutíveis.
B16: Princípio único: o executante nunca ganha em cima de custo que a empresa bancou por ele.
A18: 3. AVARIA NO TRANSBORDO | B18: REGRA AINDA A DEFINIR. O modelo já suporta: o checklist de TRANSBORDO fotografa o veículo na troca de mãos e é ele que determina em qual trecho a avaria apareceu.
B19: Enquanto a regra não é fechada, a decisão fica em OCORRENCIAS.RESPONSABILIDADE (EXECUTANTE / EMPRESA / CLIENTE).
B20: Ocorrência com RESPONSABILIDADE=EXECUTANTE e STATUS=APROVADA vira desconto no acerto do período (não no trecho).
A22: 4. ALTERAÇÃO DE FRETE | B22: NINGUÉM SEM LOG. VALOR_FRETE_ORIGINAL é congelado no lançamento. Se VALOR_FRETE mudar e não houver linha correspondente
B23: em HISTORICO_LOG, a coluna CONTROLE_FRETE marca 'BLOQUEAR: SEM LOG'. Em planilha isso é uma trava visual; em sistema é bloqueio real.
A25: 5. SEGURO / FIPE | B25: Operação é quase 100% SEMINOVO → a base do seguro é a FIPE, consultada pela placa. Guardar SEMPRE o COD_FIPE e o
B26: MES_REF_FIPE usado: a FIPE muda todo mês e sem a referência não há como auditar o prêmio depois.
B27: Para o 0km eventual, a base é o valor da nota fiscal (MES_REF_FIPE = 'NF').
B28: Consulta placa → FIPE exige API. Não existe em planilha; é requisito do sistema.
A30: STATUS DO VEÍCULO | B30: AGUARDANDO_ROTA → EM_ROTA → ROTA_CONFIRMADA → COLETADO → EM_TRANSITO → ENTREGUE → FATURADO (ou CANCELADO)
A32: ABAS | B32: Cadastro: CLIENTES · LOCAIS · MOTORISTAS (inclui terceiros) · CEGONHAS
B33: Movimento: PEDIDOS · ITENS_PEDIDO · CARGAS · TRECHOS · CUSTOS · CHECKLIST · OCORRENCIAS
B34: Saída: FATURAMENTO_MOTORISTA · PAINEL · ROMANEIO | Auditoria: HISTORICO_LOG

Sheet PARAMETROS
A1: PARÂMETRO | B1: VALOR | C1: OBSERVAÇÃO
A2: Taxa de seguro (% sobre valor segurado) | B2: 0.0003 | C2: Ad valorem. Ajustar conforme apólice (RCTR-C / RCF-DC).
A3: Início do período de apuração | B3: 46204 | C3: Usado no faturamento por motorista e nos descontos de ocorrência.
A4: Fim do período de apuração | B4: 46234 | C4: Idem.
A5: Critério de rateio da receita | B5: KM | C5: CONFIRMADO: peso do trecho proporcional ao km rodado.
A6: Base de remuneração | B6: LIQUIDA | C6: CONFIRMADO: frete menos custos dedutíveis.
A7: Rateio do custo de carga entre veículos | B7: RECEITA | C7: Custo de pedágio/combustível da carga é dividido na proporção da receita de cada veículo.
A8: Remuneração R$/KM | B8: POR CARGA | C8: IMPORTANTE: km é da viagem, não do veículo. O valor da carga é rateado entre os veículos dela.

Sheet CLIENTES
A1: ID_CLIENTE | B1: RAZAO_SOCIAL | C1: CNPJ | D1: CONTATO | E1: EMAIL | F1: TELEFONE | G1: PRAZO_PAGTO_DIAS | H1: TABELA_PRECO | I1: ATIVO
A2: CLI-001 | B2: Rede Beta Seminovos S/A | C2: 22.222.222/0001-22 | D2: Fernanda Lima | E2: fernanda@beta.com.br | F2: (41) 98888-0002 | G2: 21 | H2: TAB-PADRAO | I2: SIM
A3: CLI-002 | B3: Concessionária Alfa Ltda | C3: 11.111.111/0001-11 | D3: Marcos Silva | E3: marcos@alfa.com.br | F3: (45) 99999-0001 | G3: 30 | H3: TAB-SUL | I3: SIM
A4: CLI-003 | B4: Montadora Gama do Brasil | C4: 33.333.333/0001-33 | D4: Ricardo Souza | E4: ricardo@gama.com.br | F4: (11) 97777-0003 | G4: 45 | H4: TAB-MONTADORA | I4: SIM

Sheet LOCAIS
A1: ID_LOCAL | B1: NOME | C1: TIPO | D1: ENDERECO | E1: CIDADE | F1: UF | G1: CEP | H1: CONTATO | I1: TELEFONE | J1: HORARIO_RECEBIMENTO | K1: RESTRICOES
A2: LOC-001 | B2: Pátio Beta Seminovos Campinas | C2: PATIO | D2: Rod. Anhanguera, km 60 | E2: Campinas | F2: SP | G2: 13000-000 | H2: Portaria | I2: (19) 3333-0001 | J2: 07h-17h | K2: Agendamento obrigatório
A3: LOC-002 | B3: Concessionária Alfa Cascavel | C3: CONCESSIONARIA | D3: Av. Brasil, 1200 | E3: Cascavel | F3: PR | G3: 85800-000 | H3: Marcos | I3: (45) 99999-0001 | J3: 08h-18h | K3: Rua estreita: descarga na via
A4: LOC-003 | B4: Beta Seminovos Curitiba | C4: CONCESSIONARIA | D4: Av. das Torres, 900 | E4: Curitiba | F4: PR | G4: 81000-000 | H4: Fernanda | I4: (41) 98888-0002 | J4: 08h-17h | K4: -
A5: LOC-004 | B5: Transbordo Registro | C5: PATIO | D5: BR-116, km 440 | E5: Registro | F5: SP | G5: 11900-000 | H5: Base | I5: (13) 3822-0004 | J5: 24h | K5: Ponto de troca de carga
A6: LOC-005 | B6: Concessionária Alfa Maringá | C6: CONCESSIONARIA | D6: Av. Colombo, 5000 | E6: Maringá | F6: PR | G6: 87000-000 | H6: Juliana | I6: (44) 96666-0005 | J6: 08h-18h | K6: -

Sheet MOTORISTAS
A1: ID_MOTORISTA | B1: NOME | C1: CPF | D1: CNH | E1: VALIDADE_CNH | F1: VINCULO | G1: TRANSPORTADORA_TERCEIRO | H1: REGRA_REMUNERACAO | I1: PARAMETRO | J1: CHAVE_PIX | K1: ATIVO
A2: MOT-001 | B2: João Pereira | C2: 111.111.111-11 | D2: 01234567 | E2: 46537 | F2: FROTA | G2: - | H2: %_FRETE | I2: 0.12 | J2: 111.111.111-11 | K2: SIM
A3: MOT-002 | B3: Carlos Amaral | C3: 222.222.222-22 | D3: 02345678 | E3: 46341 | F3: FROTA | G3: - | H3: R$/KM | I3: 1.1 | J3: 222.222.222-22 | K3: SIM
A4: MOT-003 | B4: Anderson Rocha | C4: 333.333.333-33 | D4: 03456789 | E4: 46803 | F4: AGREGADO | G4: - | H4: %_FRETE | I4: 0.65 | J4: 333.333.333-33 | K4: SIM
A5: TER-001 | B5: Cegonha Sul Transportes | C5: - | D5: - | F5: TERCEIRO | G5: Cegonha Sul Transportes Ltda | H5: %_FRETE | I5: 0.7 | J5: 44.444.444/0001-44 | K5: SIM
A6: TER-002 | B6: Rodo Leste Cegonhas | C6: - | D6: - | F6: TERCEIRO | G6: Rodo Leste Cegonhas ME | H6: FIXO_VEICULO | I6: 320 | J6: 55.555.555/0001-55 | K6: SIM
B8: PARAMETRO: se a regra for %_FRETE use fração (0,12 = 12%). Se for R$/KM ou FIXO_VEICULO use valor em reais.

Sheet CEGONHAS
A1: ID_CEGONHA | B1: PLACA_CAVALO | C1: PLACA_CARRETA | D1: TIPO | E1: CAPACIDADE_VAGAS | F1: PROPRIEDADE | G1: TERCEIRO_PROPRIETARIO | H1: ATIVO
A2: CEG-001 | B2: ABC1D23 | C2: DEF4G56 | D2: CEGONHA 8 VAGAS | E2: 8 | F2: FROTA | G2: - | H2: SIM
A3: CEG-002 | B3: HIJ7K89 | C3: LMN0P12 | D3: CEGONHA 11 VAGAS | E3: 11 | F3: FROTA | G3: - | H3: SIM
A4: CEG-003 | B4: QRS3T45 | C4: UVW6X78 | D4: CEGONHA 8 VAGAS | E4: 8 | F4: TERCEIRO | G4: Cegonha Sul Transportes Ltda | H4: SIM

Sheet PEDIDOS
A1: ID_PEDIDO | B1: DATA_SOLICITACAO | C1: ID_CLIENTE | D1: SOLICITANTE_CLIENTE | E1: RESPONSAVEL_COMERCIAL | F1: STATUS_COMERCIAL | G1: PRAZO_PROMETIDO | H1: QTDE_VEICULOS | I1: VALOR_TOTAL_PEDIDO | J1: VEICULOS_ENTREGUES | K1: OBSERVACAO
A2: PED-001 | B2: 46204 | C2: CLI-001 | D2: Fernanda Lima | E2: Ana (Comercial) | F2: CONFIRMADO | G2: 46213 | H2: =COUNTIFS(ITENS_PEDIDO!$B:$B,$A2) -> 6 | I2: =SUMIFS(ITENS_PEDIDO!$Q:$Q,ITENS_PEDIDO!$B:$B,$A2) -> 7650 | J2: =COUNTIFS(ITENS_PEDIDO!$B:$B,$A2,ITENS_PEDIDO!$S:$S,"ENTREGUE") -> 6 | K2: Seminovos de leilão
A3: PED-002 | B3: 46206 | C3: CLI-002 | D3: Marcos Silva | E3: Bruno (Comercial) | F3: CONFIRMADO | G3: 46215 | H3: =COUNTIFS(ITENS_PEDIDO!$B:$B,$A3) -> 6 | I3: =SUMIFS(ITENS_PEDIDO!$Q:$Q,ITENS_PEDIDO!$B:$B,$A3) -> 4300 | J3: =COUNTIFS(ITENS_PEDIDO!$B:$B,$A3,ITENS_PEDIDO!$S:$S,"ENTREGUE") -> 0 | K3: Repasse entre lojas
A4: PED-003 | B4: 46211 | C4: CLI-003 | D4: Ricardo Souza | E4: Ana (Comercial) | F4: EM_NEGOCIACAO | G4: 46223 | H4: =COUNTIFS(ITENS_PEDIDO!$B:$B,$A4) -> 1 | I4: =SUMIFS(ITENS_PEDIDO!$Q:$Q,ITENS_PEDIDO!$B:$B,$A4) -> 1500 | J4: =COUNTIFS(ITENS_PEDIDO!$B:$B,$A4,ITENS_PEDIDO!$S:$S,"ENTREGUE") -> 0 | K4: 0km — aguardando preço

Sheet ITENS_PEDIDO
A1: ID_ITEM | B1: ID_PEDIDO | C1: CHASSI | D1: PLACA_VEICULO | E1: MARCA | F1: MODELO | G1: ANO | H1: TIPO | I1: COD_FIPE | J1: MES_REF_FIPE | K1: VALOR_SEGURADO | L1: CIDADE_ORIGEM | M1: UF_ORIGEM | N1: CIDADE_DESTINO | O1: UF_DESTINO | P1: VALOR_FRETE_ORIGINAL | Q1: VALOR_FRETE | R1: KM_TOTAL | S1: STATUS_OPERACIONAL | T1: DATA_CONFIRMACAO_ROTA | U1: PREVISAO_COLETA | V1: DATA_COLETA_REAL | W1: PREVISAO_ENTREGA | X1: DATA_ENTREGA_REAL | Y1: VALOR_SEGURO | Z1: CUSTO_EXECUTANTES | AA1: CUSTOS_EMPRESA | AB1: MARGEM_ITEM | AC1: CHECK_RATEIO | AD1: CONTROLE_FRETE
A2: IT-001 | B2: PED-001 | C2: 9BW111111X1111111 | D2: ABC-1111 | E2: Beta | F2: Compacto 1.0 | G2: 2022 | H2: SEMINOVO | I2: 001234-5 | J2: 07/2026 | K2: 58000 | L2: Campinas | M2: SP | N2: Cascavel | O2: PR | P2: 1300 | Q2: 1400 | R2: 850 | S2: ENTREGUE | T2: 46205 | U2: 46206 | V2: 46206 | W2: 46209 | X2: 46209 | Y2: =$K2*PARAMETROS!$B$2 -> 17.4 | Z2: =SUMIFS(TRECHOS!$W:$W,TRECHOS!$B:$B,$A2) -> 597.88235 | AA2: =SUMIFS(TRECHOS!$R:$R,TRECHOS!$B:$B,$A2) -> 205.78313 | AB2: =$Q2-$Z2-$AA2-$Y2 -> 578.93451 | AC2: =IF($S2="AGUARDANDO_ROTA","SEM ROTA",IF(ROUND(SUMIFS(TRECHOS!$L:$L,TRECHOS!$B:$B,$A2),4)=1,"OK","REVISAR")) -> OK | AD2: =IF($Q2=$P2,"-",IF(COUNTIFS(HISTORICO_LOG!$D:$D,$A2,HISTORICO_LOG!$E:$E,"VALOR_FRETE")>0,"ALTERADO C/ LOG","BLOQUEAR: SEM LOG")) -> ALTERADO C/ LOG
A3: IT-002 | B3: PED-001 | C3: 9BW222222X2222222 | D3: DEF-2222 | E3: Beta | F3: SUV 2.0 | G3: 2021 | H3: SEMINOVO | I3: 002345-6 | J3: 07/2026 | K3: 132000 | L3: Campinas | M3: SP | N3: Cascavel | O3: PR | P3: 1350 | Q3: 1350 | R3: 850 | S3: ENTREGUE | T3: 46205 | U3: 46206 | V3: 46206 | W3: 46209 | X3: 46209 | Y3: =$K3*PARAMETROS!$B$2 -> 39.6 | Z3: =SUMIFS(TRECHOS!$W:$W,TRECHOS!$B:$B,$A3) -> 576.52941 | AA3: =SUMIFS(TRECHOS!$R:$R,TRECHOS!$B:$B,$A3) -> 198.43373 | AB3: =$Q3-$Z3-$AA3-$Y3 -> 535.43685 | AC3: =IF($S3="AGUARDANDO_ROTA","SEM ROTA",IF(ROUND(SUMIFS(TRECHOS!$L:$L,TRECHOS!$B:$B,$A3),4)=1,"OK","REVISAR")) -> OK | AD3: =IF($Q3=$P3,"-",IF(COUNTIFS(HISTORICO_LOG!$D:$D,$A3,HISTORICO_LOG!$E:$E,"VALOR_FRETE")>0,"ALTERADO C/ LOG","BLOQUEAR: SEM LOG")) -> -
A4: IT-003 | B4: PED-001 | C4: 9BW333333X3333333 | D4: GHI-3333 | E4: Beta | F4: Hatch 1.6 | G4: 2023 | H4: SEMINOVO | I4: 003456-7 | J4: 07/2026 | K4: 76000 | L4: Campinas | M4: SP | N4: Cascavel | O4: PR | P4: 1300 | Q4: 1300 | R4: 850 | S4: ENTREGUE | T4: 46205 | U4: 46206 | V4: 46206 | W4: 46209 | X4: 46209 | Y4: =$K4*PARAMETROS!$B$2 -> 22.8 | Z4: =SUMIFS(TRECHOS!$W:$W,TRECHOS!$B:$B,$A4) -> 555.17647 | AA4: =SUMIFS(TRECHOS!$R:$R,TRECHOS!$B:$B,$A4) -> 191.08434 | AB4: =$Q4-$Z4-$AA4-$Y4 -> 530.93919 | AC4: =IF($S4="AGUARDANDO_ROTA","SEM ROTA",IF(ROUND(SUMIFS(TRECHOS!$L:$L,TRECHOS!$B:$B,$A4),4)=1,"OK","REVISAR")) -> OK | AD4: =IF($Q4=$P4,"-",IF(COUNTIFS(HISTORICO_LOG!$D:$D,$A4,HISTORICO_LOG!$E:$E,"VALOR_FRETE")>0,"ALTERADO C/ LOG","BLOQUEAR: SEM LOG")) -> -
A5: IT-004 | B5: PED-001 | C5: 9BW444444X4444444 | D5: JKL-4444 | E5: Beta | F5: Sedan 1.8 | G5: 2022 | H5: SEMINOVO | I5: 004567-8 | J5: 07/2026 | K5: 92000 | L5: Campinas | M5: SP | N5: Maringá | O5: PR | P5: 1250 | Q5: 1250 | R5: 720 | S5: ENTREGUE | T5: 46205 | U5: 46206 | V5: 46206 | W5: 46209 | X5: 46210 | Y5: =$K5*PARAMETROS!$B$2 -> 27.6 | Z5: =SUMIFS(TRECHOS!$W:$W,TRECHOS!$B:$B,$A5) -> 472.22222 | AA5: =SUMIFS(TRECHOS!$R:$R,TRECHOS!$B:$B,$A5) -> 216.9093 | AB5: =$Q5-$Z5-$AA5-$Y5 -> 533.26847 | AC5: =IF($S5="AGUARDANDO_ROTA","SEM ROTA",IF(ROUND(SUMIFS(TRECHOS!$L:$L,TRECHOS!$B:$B,$A5),4)=1,"OK","REVISAR")) -> OK | AD5: =IF($Q5=$P5,"-",IF(COUNTIFS(HISTORICO_LOG!$D:$D,$A5,HISTORICO_LOG!$E:$E,"VALOR_FRETE")>0,"ALTERADO C/ LOG","BLOQUEAR: SEM LOG")) -> -
A6: IT-005 | B6: PED-001 | C6: 9BW555555X5555555 | D6: MNO-5555 | E6: Beta | F6: SUV Compacto | G6: 2023 | H6: SEMINOVO | I6: 005678-9 | J6: 07/2026 | K6: 118000 | L6: Campinas | M6: SP | N6: Maringá | O6: PR | P6: 1200 | Q6: 1200 | R6: 720 | S6: ENTREGUE | T6: 46205 | U6: 46206 | V6: 46206 | W6: 46209 | X6: 46210 | Y6: =$K6*PARAMETROS!$B$2 -> 35.4 | Z6: =SUMIFS(TRECHOS!$W:$W,TRECHOS!$B:$B,$A6) -> 453.33333 | AA6: =SUMIFS(TRECHOS!$R:$R,TRECHOS!$B:$B,$A6) -> 208.23293 | AB6: =$Q6-$Z6-$AA6-$Y6 -> 503.03373 | AC6: =IF($S6="AGUARDANDO_ROTA","SEM ROTA",IF(ROUND(SUMIFS(TRECHOS!$L:$L,TRECHOS!$B:$B,$A6),4)=1,"OK","REVISAR")) -> OK | AD6: =IF($Q6=$P6,"-",IF(COUNTIFS(HISTORICO_LOG!$D:$D,$A6,HISTORICO_LOG!$E:$E,"VALOR_FRETE")>0,"ALTERADO C/ LOG","BLOQUEAR: SEM LOG")) -> -
A7: IT-006 | B7: PED-001 | C7: 9BW666666X6666666 | D7: PQR-6666 | E7: Beta | F7: Picape 2.8 | G7: 2021 | H7: SEMINOVO | I7: 006789-0 | J7: 07/2026 | K7: 180000 | L7: Campinas | M7: SP | N7: Maringá | O7: PR | P7: 1150 | Q7: 1150 | R7: 720 | S7: ENTREGUE | T7: 46205 | U7: 46206 | V7: 46206 | W7: 46209 | X7: 46210 | Y7: =$K7*PARAMETROS!$B$2 -> 54 | Z7: =SUMIFS(TRECHOS!$W:$W,TRECHOS!$B:$B,$A7) -> 434.44444 | AA7: =SUMIFS(TRECHOS!$R:$R,TRECHOS!$B:$B,$A7) -> 199.55656 | AB7: =$Q7-$Z7-$AA7-$Y7 -> 461.999 | AC7: =IF($S7="AGUARDANDO_ROTA","SEM ROTA",IF(ROUND(SUMIFS(TRECHOS!$L:$L,TRECHOS!$B:$B,$A7),4)=1,"OK","REVISAR")) -> OK | AD7: =IF($Q7=$P7,"-",IF(COUNTIFS(HISTORICO_LOG!$D:$D,$A7,HISTORICO_LOG!$E:$E,"VALOR_FRETE")>0,"ALTERADO C/ LOG","BLOQUEAR: SEM LOG")) -> -
A8: IT-007 | B8: PED-002 | C8: 9BW777777X7777777 | D8: STU-7777 | E8: Alfa | F8: Sedan Plus | G8: 2023 | H8: SEMINOVO | I8: 007890-1 | J8: 07/2026 | K8: 110000 | L8: Curitiba | M8: PR | N8: Cascavel | O8: PR | P8: 600 | Q8: 620 | R8: 500 | S8: EM_TRANSITO | T8: 46208 | U8: 46211 | V8: 46211 | W8: 46214 | Y8: =$K8*PARAMETROS!$B$2 -> 33 | Z8: =SUMIFS(TRECHOS!$W:$W,TRECHOS!$B:$B,$A8) -> 170.5 | AA8: =SUMIFS(TRECHOS!$R:$R,TRECHOS!$B:$B,$A8) -> 238.7 | AB8: =$Q8-$Z8-$AA8-$Y8 -> 177.8 | AC8: =IF($S8="AGUARDANDO_ROTA","SEM ROTA",IF(ROUND(SUMIFS(TRECHOS!$L:$L,TRECHOS!$B:$B,$A8),4)=1,"OK","REVISAR")) -> OK | AD8: =IF($Q8=$P8,"-",IF(COUNTIFS(HISTORICO_LOG!$D:$D,$A8,HISTORICO_LOG!$E:$E,"VALOR_FRETE")>0,"ALTERADO C/ LOG","BLOQUEAR: SEM LOG")) -> BLOQUEAR: SEM LOG
A9: IT-008 | B9: PED-002 | C9: 9BW888888X8888888 | D9: VWX-8888 | E9: Alfa | F9: Hatch Sport | G9: 2022 | H9: SEMINOVO | I9: 008901-2 | J9: 07/2026 | K9: 84000 | L9: Curitiba | M9: PR | N9: Cascavel | O9: PR | P9: 700 | Q9: 700 | R9: 500 | S9: EM_TRANSITO | T9: 46208 | U9: 46211 | V9: 46211 | W9: 46214 | Y9: =$K9*PARAMETROS!$B$2 -> 25.2 | Z9: =SUMIFS(TRECHOS!$W:$W,TRECHOS!$B:$B,$A9) -> 192.5 | AA9: =SUMIFS(TRECHOS!$R:$R,TRECHOS!$B:$B,$A9) -> 269.5 | AB9: =$Q9-$Z9-$AA9-$Y9 -> 212.8 | AC9: =IF($S9="AGUARDANDO_ROTA","SEM ROTA",IF(ROUND(SUMIFS(TRECHOS!$L:$L,TRECHOS!$B:$B,$A9),4)=1,"OK","REVISAR")) -> OK | AD9: =IF($Q9=$P9,"-",IF(COUNTIFS(HISTORICO_LOG!$D:$D,$A9,HISTORICO_LOG!$E:$E,"VALOR_FRETE")>0,"ALTERADO C/ LOG","BLOQUEAR: SEM LOG")) -> -
A10: IT-009 | B10: PED-002 | C10: 9BW999999X9999999 | D10: YZA-9999 | E10: Alfa | F10: SUV 1.4T | G10: 2023 | H10: SEMINOVO | I10: 009012-3 | J10: 07/2026 | K10: 145000 | L10: Curitiba | M10: PR | N10: Cascavel | O10: PR | P10: 680 | Q10: 680 | R10: 500 | S10: EM_TRANSITO | T10: 46208 | U10: 46211 | V10: 46211 | W10: 46214 | Y10: =$K10*PARAMETROS!$B$2 -> 43.5 | Z10: =SUMIFS(TRECHOS!$W:$W,TRECHOS!$B:$B,$A10) -> 187 | AA10: =SUMIFS(TRECHOS!$R:$R,TRECHOS!$B:$B,$A10) -> 261.8 | AB10: =$Q10-$Z10-$AA10-$Y10 -> 187.7 | AC10: =IF($S10="AGUARDANDO_ROTA","SEM ROTA",IF(ROUND(SUMIFS(TRECHOS!$L:$L,TRECHOS!$B:$B,$A10),4)=1,"OK","REVISAR")) -> OK | AD10: =IF($Q10=$P10,"-",IF(COUNTIFS(HISTORICO_LOG!$D:$D,$A10,HISTORICO_LOG!$E:$E,"VALOR_FRETE")>0,"ALTERADO C/ LOG","BLOQUEAR: SEM LOG")) -> -
A11: IT-010 | B11: PED-002 | C11: 9BWAAAAAAXAAAAAA1 | D11: BCD-1010 | E11: Alfa | F11: Compacto 1.0 | G11: 2021 | H11: SEMINOVO | I11: 010123-4 | J11: 07/2026 | K11: 62000 | L11: Curitiba | M11: PR | N11: Maringá | O11: PR | P11: 750 | Q11: 750 | R11: 460 | S11: COLETADO | T11: 46208 | U11: 46212 | V11: 46212 | W11: 46215 | Y11: =$K11*PARAMETROS!$B$2 -> 18.6 | Z11: =SUMIFS(TRECHOS!$W:$W,TRECHOS!$B:$B,$A11) -> 336.53226 | AA11: =SUMIFS(TRECHOS!$R:$R,TRECHOS!$B:$B,$A11) -> 382.25806 | AB11: =$Q11-$Z11-$AA11-$Y11 -> 12.609677 | AC11: =IF($S11="AGUARDANDO_ROTA","SEM ROTA",IF(ROUND(SUMIFS(TRECHOS!$L:$L,TRECHOS!$B:$B,$A11),4)=1,"OK","REVISAR")) -> OK | AD11: =IF($Q11=$P11,"-",IF(COUNTIFS(HISTORICO_LOG!$D:$D,$A11,HISTORICO_LOG!$E:$E,"VALOR_FRETE")>0,"ALTERADO C/ LOG","BLOQUEAR: SEM LOG")) -> -
A12: IT-011 | B12: PED-002 | C12: 9BWBBBBBBXBBBBBB2 | D12: EFG-1111 | E12: Alfa | F12: Sedan 2.0 | G12: 2022 | H12: SEMINOVO | I12: 011234-5 | J12: 07/2026 | K12: 98000 | L12: Curitiba | M12: PR | N12: Maringá | O12: PR | P12: 800 | Q12: 800 | R12: 460 | S12: COLETADO | T12: 46208 | U12: 46212 | V12: 46212 | W12: 46215 | Y12: =$K12*PARAMETROS!$B$2 -> 29.4 | Z12: =SUMIFS(TRECHOS!$W:$W,TRECHOS!$B:$B,$A12) -> 358.96774 | AA12: =SUMIFS(TRECHOS!$R:$R,TRECHOS!$B:$B,$A12) -> 247.74194 | AB12: =$Q12-$Z12-$AA12-$Y12 -> 163.89032 | AC12: =IF($S12="AGUARDANDO_ROTA","SEM ROTA",IF(ROUND(SUMIFS(TRECHOS!$L:$L,TRECHOS!$B:$B,$A12),4)=1,"OK","REVISAR")) -> OK | AD12: =IF($Q12=$P12,"-",IF(COUNTIFS(HISTORICO_LOG!$D:$D,$A12,HISTORICO_LOG!$E:$E,"VALOR_FRETE")>0,"ALTERADO C/ LOG","BLOQUEAR: SEM LOG")) -> -
A13: IT-012 | B13: PED-002 | C13: 9BWCCCCCCXCCCCCC3 | D13: HIJ-1212 | E13: Alfa | F13: SUV 2.0 Diesel | G13: 2023 | H13: SEMINOVO | I13: 012345-6 | J13: 07/2026 | K13: 195000 | L13: Curitiba | M13: PR | N13: Maringá | O13: PR | P13: 750 | Q13: 750 | R13: 460 | S13: ROTA_CONFIRMADA | T13: 46208 | U13: 46216 | W13: 46218 | Y13: =$K13*PARAMETROS!$B$2 -> 58.5 | Z13: =SUMIFS(TRECHOS!$W:$W,TRECHOS!$B:$B,$A13) -> 320 | AA13: =SUMIFS(TRECHOS!$R:$R,TRECHOS!$B:$B,$A13) -> 0 | AB13: =$Q13-$Z13-$AA13-$Y13 -> 371.5 | AC13: =IF($S13="AGUARDANDO_ROTA","SEM ROTA",IF(ROUND(SUMIFS(TRECHOS!$L:$L,TRECHOS!$B:$B,$A13),4)=1,"OK","REVISAR")) -> OK | AD13: =IF($Q13=$P13,"-",IF(COUNTIFS(HISTORICO_LOG!$D:$D,$A13,HISTORICO_LOG!$E:$E,"VALOR_FRETE")>0,"ALTERADO C/ LOG","BLOQUEAR: SEM LOG")) -> -
A14: IT-013 | B14: PED-003 | C14: 9BWDDDDDDXDDDDDD4 | D14: 0KM-0001 | E14: Gama | F14: Sedan LX | G14: 2026 | H14: 0KM | I14: - | J14: NF | K14: 95000 | L14: Cascavel | M14: PR | N14: Campinas | O14: SP | P14: 1500 | Q14: 1500 | R14: 850 | S14: AGUARDANDO_ROTA | Y14: =$K14*PARAMETROS!$B$2 -> 28.5 | Z14: =SUMIFS(TRECHOS!$W:$W,TRECHOS!$B:$B,$A14) -> 0 | AA14: =SUMIFS(TRECHOS!$R:$R,TRECHOS!$B:$B,$A14) -> 0 | AB14: =$Q14-$Z14-$AA14-$Y14 -> 1471.5 | AC14: =IF($S14="AGUARDANDO_ROTA","SEM ROTA",IF(ROUND(SUMIFS(TRECHOS!$L:$L,TRECHOS!$B:$B,$A14),4)=1,"OK","REVISAR")) -> SEM ROTA | AD14: =IF($Q14=$P14,"-",IF(COUNTIFS(HISTORICO_LOG!$D:$D,$A14,HISTORICO_LOG!$E:$E,"VALOR_FRETE")>0,"ALTERADO C/ LOG","BLOQUEAR: SEM LOG")) -> -

Sheet CARGAS
A1: ID_CARGA | B1: DATA_PROGRAMADA | C1: ROTA | D1: ID_CEGONHA | E1: ID_MOTORISTA_PRINCIPAL | F1: TIPO_OPERACAO | G1: RESPONSAVEL_LOGISTICA | H1: STATUS_CARGA | I1: KM_ROTA | J1: QTDE_VEICULOS | K1: RECEITA_ATRIBUIDA | L1: CUSTO_EXECUTANTES | M1: CUSTOS_OPERACIONAIS | N1: MARGEM_CARGA | O1: CHECKLIST_COLETA_OK | P1: CHECKLIST_ENTREGA_OK | Q1: DATA_SAIDA | R1: DATA_CHEGADA
A2: CAR-001 | B2: 46206 | C2: Campinas/SP → Registro/SP (6 veículos) | D2: CEG-002 | E2: MOT-001 | F2: FROTA | G2: Paula (Logística) | H2: CONCLUIDA | I2: 400 | J2: =COUNTIFS(TRECHOS!$D:$D,$A2) -> 6 | K2: =SUMIFS(TRECHOS!$N:$N,TRECHOS!$D:$D,$A2) -> 3905.8824 | L2: =SUMIFS(TRECHOS!$W:$W,TRECHOS!$D:$D,$A2) -> 468.70588 | M2: =SUMIFS(TRECHOS!$R:$R,TRECHOS!$D:$D,$A2) -> 1220 | N2: =$K2-$L2-$M2 -> 2217.1765 | O2: SIM | P2: SIM | Q2: 46206 | R2: 46207
A3: CAR-002 | B3: 46207 | C3: Registro/SP → Cascavel e Maringá/PR | D3: CEG-003 | E3: TER-001 | F3: TERCEIRO | G3: Paula (Logística) | H3: CONCLUIDA | I3: 780 | J3: =COUNTIFS(TRECHOS!$D:$D,$A3) -> 6 | K3: =SUMIFS(TRECHOS!$N:$N,TRECHOS!$D:$D,$A3) -> 3744.1176 | L3: =SUMIFS(TRECHOS!$W:$W,TRECHOS!$D:$D,$A3) -> 2620.8824 | M3: =SUMIFS(TRECHOS!$R:$R,TRECHOS!$D:$D,$A3) -> 0 | N3: =$K3-$L3-$M3 -> 1123.2353 | O3: SIM | P3: SIM | Q3: 46207 | R3: 46210
A4: CAR-003 | B4: 46211 | C4: Curitiba/PR → Cascavel/PR (3 veículos) | D4: CEG-001 | E4: MOT-002 | F4: FROTA | G4: Paula (Logística) | H4: EM_TRANSITO | I4: 500 | J4: =COUNTIFS(TRECHOS!$D:$D,$A4) -> 3 | K4: =SUMIFS(TRECHOS!$N:$N,TRECHOS!$D:$D,$A4) -> 2000 | L4: =SUMIFS(TRECHOS!$W:$W,TRECHOS!$D:$D,$A4) -> 550 | M4: =SUMIFS(TRECHOS!$R:$R,TRECHOS!$D:$D,$A4) -> 770 | N4: =$K4-$L4-$M4 -> 680 | O4: SIM | P4: NAO | Q4: 46211
A5: CAR-004 | B5: 46212 | C5: Curitiba/PR → Maringá/PR (2 veículos) | D5: CEG-002 | E5: MOT-003 | F5: AGREGADO | G5: Paula (Logística) | H5: EM_TRANSITO | I5: 460 | J5: =COUNTIFS(TRECHOS!$D:$D,$A5) -> 2 | K5: =SUMIFS(TRECHOS!$N:$N,TRECHOS!$D:$D,$A5) -> 1550 | L5: =SUMIFS(TRECHOS!$W:$W,TRECHOS!$D:$D,$A5) -> 695.5 | M5: =SUMIFS(TRECHOS!$R:$R,TRECHOS!$D:$D,$A5) -> 630 | N5: =$K5-$L5-$M5 -> 224.5 | O5: SIM | P5: NAO | Q5: 46212
A6: CAR-005 | B6: 46216 | C6: Curitiba/PR → Maringá/PR (1 veículo) | D6: CEG-002 | E6: TER-002 | F6: TERCEIRO | G6: Paula (Logística) | H6: PROGRAMADA | I6: 460 | J6: =COUNTIFS(TRECHOS!$D:$D,$A6) -> 1 | K6: =SUMIFS(TRECHOS!$N:$N,TRECHOS!$D:$D,$A6) -> 750 | L6: =SUMIFS(TRECHOS!$W:$W,TRECHOS!$D:$D,$A6) -> 320 | M6: =SUMIFS(TRECHOS!$R:$R,TRECHOS!$D:$D,$A6) -> 0 | N6: =$K6-$L6-$M6 -> 430 | O6: NAO | P6: NAO

Sheet TRECHOS
A1: ID_TRECHO | B1: ID_ITEM | C1: SEQ | D1: ID_CARGA | E1: DATA_REF | F1: ID_LOCAL_ORIGEM | G1: ID_LOCAL_DESTINO | H1: KM_TRECHO | I1: ID_EXECUTANTE | J1: PESO_AUTO_KM | K1: PESO_MANUAL | L1: PESO_APLICADO | M1: VALOR_FRETE_ITEM | N1: RECEITA_TRECHO | O1: PART_NA_CARGA | P1: CUSTO_DEDUT_DIRETO | Q1: CUSTO_DEDUT_RATEADO | R1: CUSTO_EMPRESA_TOTAL | S1: BASE_CALCULO | T1: VINCULO | U1: REGRA | V1: PARAMETRO | W1: REMUNERACAO_EXECUTANTE | X1: MARGEM_TRECHO | Y1: CHECK_RATEIO
A2: TRE-001 | B2: IT-001 | C2: 1 | D2: CAR-001 | E2: =IFERROR(INDEX(CARGAS!$B:$B,MATCH($D2,CARGAS!$A:$A,0)),"") -> 46206 | F2: LOC-001 | G2: LOC-004 | H2: 400 | I2: MOT-001 | J2: =IFERROR($H2/SUMIFS($H:$H,$B:$B,$B2),0) -> 0.47058824 | L2: =IF($K2="",$J2,$K2) -> 0.47058824 | M2: =IFERROR(INDEX(ITENS_PEDIDO!$Q:$Q,MATCH($B2,ITENS_PEDIDO!$A:$A,0)),0) -> 1400 | N2: =$L2*$M2 -> 658.82353 | O2: =IFERROR($N2/SUMIFS($N:$N,$D:$D,$D2),0) -> 0.1686747 | P2: =SUMIFS(CUSTOS!$H:$H,CUSTOS!$D:$D,$A2,CUSTOS!$J:$J,"SIM") -> 0 | Q2: =$O2*SUMIFS(CUSTOS!$H:$H,CUSTOS!$C:$C,$D2,CUSTOS!$B:$B,"CARGA",CUSTOS!$J:$J,"SIM") -> 0 | R2: =SUMIFS(CUSTOS!$H:$H,CUSTOS!$D:$D,$A2,CUSTOS!$I:$I,"EMPRESA")+$O2*SUMIFS(CUSTOS!$H:$H,CUSTOS!$C:$C,$D2,CUSTOS!$B:$B,"CARGA",CUSTOS!$I:$I,"EMPRESA") -> 205.78313 | S2: =$N2-$P2-$Q2 -> 658.82353 | T2: =IFERROR(INDEX(MOTORISTAS!$F:$F,MATCH($I2,MOTORISTAS!$A:$A,0)),"") -> FROTA | U2: =IFERROR(INDEX(MOTORISTAS!$H:$H,MATCH($I2,MOTORISTAS!$A:$A,0)),"") -> %_FRETE | V2: =IFERROR(INDEX(MOTORISTAS!$I:$I,MATCH($I2,MOTORISTAS!$A:$A,0)),0) -> 0.12 | W2: =MAX(0,IF($U2="%_FRETE",$S2*$V2,IF($U2="R$/KM",IFERROR(INDEX(CARGAS!$I:$I,MATCH($D2,CARGAS!$A:$A,0)),0)*$V2*$O2-$P2-$Q2,IF($U2="FIXO_VEICULO",$V2-$P2-$Q2,0)))) -> 79.058824 | X2: =$N2-$W2-$R2 -> 373.98157 | Y2: =IF(ROUND(SUMIFS($L:$L,$B:$B,$B2),4)=1,"OK","REVISAR") -> OK
A3: TRE-002 | B3: IT-002 | C3: 1 | D3: CAR-001 | E3: =IFERROR(INDEX(CARGAS!$B:$B,MATCH($D3,CARGAS!$A:$A,0)),"") -> 46206 | F3: LOC-001 | G3: LOC-004 | H3: 400 | I3: MOT-001 | J3: =IFERROR($H3/SUMIFS($H:$H,$B:$B,$B3),0) -> 0.47058824 | L3: =IF($K3="",$J3,$K3) -> 0.47058824 | M3: =IFERROR(INDEX(ITENS_PEDIDO!$Q:$Q,MATCH($B3,ITENS_PEDIDO!$A:$A,0)),0) -> 1350 | N3: =$L3*$M3 -> 635.29412 | O3: =IFERROR($N3/SUMIFS($N:$N,$D:$D,$D3),0) -> 0.1626506 | P3: =SUMIFS(CUSTOS!$H:$H,CUSTOS!$D:$D,$A3,CUSTOS!$J:$J,"SIM") -> 0 | Q3: =$O3*SUMIFS(CUSTOS!$H:$H,CUSTOS!$C:$C,$D3,CUSTOS!$B:$B,"CARGA",CUSTOS!$J:$J,"SIM") -> 0 | R3: =SUMIFS(CUSTOS!$H:$H,CUSTOS!$D:$D,$A3,CUSTOS!$I:$I,"EMPRESA")+$O3*SUMIFS(CUSTOS!$H:$H,CUSTOS!$C:$C,$D3,CUSTOS!$B:$B,"CARGA",CUSTOS!$I:$I,"EMPRESA") -> 198.43373 | S3: =$N3-$P3-$Q3 -> 635.29412 | T3: =IFERROR(INDEX(MOTORISTAS!$F:$F,MATCH($I3,MOTORISTAS!$A:$A,0)),"") -> FROTA | U3: =IFERROR(INDEX(MOTORISTAS!$H:$H,MATCH($I3,MOTORISTAS!$A:$A,0)),"") -> %_FRETE | V3: =IFERROR(INDEX(MOTORISTAS!$I:$I,MATCH($I3,MOTORISTAS!$A:$A,0)),0) -> 0.12 | W3: =MAX(0,IF($U3="%_FRETE",$S3*$V3,IF($U3="R$/KM",IFERROR(INDEX(CARGAS!$I:$I,MATCH($D3,CARGAS!$A:$A,0)),0)*$V3*$O3-$P3-$Q3,IF($U3="FIXO_VEICULO",$V3-$P3-$Q3,0)))) -> 76.235294 | X3: =$N3-$W3-$R3 -> 360.62509 | Y3: =IF(ROUND(SUMIFS($L:$L,$B:$B,$B3),4)=1,"OK","REVISAR") -> OK
A4: TRE-003 | B4: IT-003 | C4: 1 | D4: CAR-001 | E4: =IFERROR(INDEX(CARGAS!$B:$B,MATCH($D4,CARGAS!$A:$A,0)),"") -> 46206 | F4: LOC-001 | G4: LOC-004 | H4: 400 | I4: MOT-001 | J4: =IFERROR($H4/SUMIFS($H:$H,$B:$B,$B4),0) -> 0.47058824 | L4: =IF($K4="",$J4,$K4) -> 0.47058824 | M4: =IFERROR(INDEX(ITENS_PEDIDO!$Q:$Q,MATCH($B4,ITENS_PEDIDO!$A:$A,0)),0) -> 1300 | N4: =$L4*$M4 -> 611.76471 | O4: =IFERROR($N4/SUMIFS($N:$N,$D:$D,$D4),0) -> 0.15662651 | P4: =SUMIFS(CUSTOS!$H:$H,CUSTOS!$D:$D,$A4,CUSTOS!$J:$J,"SIM") -> 0 | Q4: =$O4*SUMIFS(CUSTOS!$H:$H,CUSTOS!$C:$C,$D4,CUSTOS!$B:$B,"CARGA",CUSTOS!$J:$J,"SIM") -> 0 | R4: =SUMIFS(CUSTOS!$H:$H,CUSTOS!$D:$D,$A4,CUSTOS!$I:$I,"EMPRESA")+$O4*SUMIFS(CUSTOS!$H:$H,CUSTOS!$C:$C,$D4,CUSTOS!$B:$B,"CARGA",CUSTOS!$I:$I,"EMPRESA") -> 191.08434 | S4: =$N4-$P4-$Q4 -> 611.76471 | T4: =IFERROR(INDEX(MOTORISTAS!$F:$F,MATCH($I4,MOTORISTAS!$A:$A,0)),"") -> FROTA | U4: =IFERROR(INDEX(MOTORISTAS!$H:$H,MATCH($I4,MOTORISTAS!$A:$A,0)),"") -> %_FRETE | V4: =IFERROR(INDEX(MOTORISTAS!$I:$I,MATCH($I4,MOTORISTAS!$A:$A,0)),0) -> 0.12 | W4: =MAX(0,IF($U4="%_FRETE",$S4*$V4,IF($U4="R$/KM",IFERROR(INDEX(CARGAS!$I:$I,MATCH($D4,CARGAS!$A:$A,0)),0)*$V4*$O4-$P4-$Q4,IF($U4="FIXO_VEICULO",$V4-$P4-$Q4,0)))) -> 73.411765 | X4: =$N4-$W4-$R4 -> 347.2686 | Y4: =IF(ROUND(SUMIFS($L:$L,$B:$B,$B4),4)=1,"OK","REVISAR") -> OK
A5: TRE-004 | B5: IT-004 | C5: 1 | D5: CAR-001 | E5: =IFERROR(INDEX(CARGAS!$B:$B,MATCH($D5,CARGAS!$A:$A,0)),"") -> 46206 | F5: LOC-001 | G5: LOC-004 | H5: 400 | I5: MOT-001 | J5: =IFERROR($H5/SUMIFS($H:$H,$B:$B,$B5),0) -> 0.55555556 | L5: =IF($K5="",$J5,$K5) -> 0.55555556 | M5: =IFERROR(INDEX(ITENS_PEDIDO!$Q:$Q,MATCH($B5,ITENS_PEDIDO!$A:$A,0)),0) -> 1250 | N5: =$L5*$M5 -> 694.44444 | O5: =IFERROR($N5/SUMIFS($N:$N,$D:$D,$D5),0) -> 0.17779451 | P5: =SUMIFS(CUSTOS!$H:$H,CUSTOS!$D:$D,$A5,CUSTOS!$J:$J,"SIM") -> 0 | Q5: =$O5*SUMIFS(CUSTOS!$H:$H,CUSTOS!$C:$C,$D5,CUSTOS!$B:$B,"CARGA",CUSTOS!$J:$J,"SIM") -> 0 | R5: =SUMIFS(CUSTOS!$H:$H,CUSTOS!$D:$D,$A5,CUSTOS!$I:$I,"EMPRESA")+$O5*SUMIFS(CUSTOS!$H:$H,CUSTOS!$C:$C,$D5,CUSTOS!$B:$B,"CARGA",CUSTOS!$I:$I,"EMPRESA") -> 216.9093 | S5: =$N5-$P5-$Q5 -> 694.44444 | T5: =IFERROR(INDEX(MOTORISTAS!$F:$F,MATCH($I5,MOTORISTAS!$A:$A,0)),"") -> FROTA | U5: =IFERROR(INDEX(MOTORISTAS!$H:$H,MATCH($I5,MOTORISTAS!$A:$A,0)),"") -> %_FRETE | V5: =IFERROR(INDEX(MOTORISTAS!$I:$I,MATCH($I5,MOTORISTAS!$A:$A,0)),0) -> 0.12 | W5: =MAX(0,IF($U5="%_FRETE",$S5*$V5,IF($U5="R$/KM",IFERROR(INDEX(CARGAS!$I:$I,MATCH($D5,CARGAS!$A:$A,0)),0)*$V5*$O5-$P5-$Q5,IF($U5="FIXO_VEICULO",$V5-$P5-$Q5,0)))) -> 83.333333 | X5: =$N5-$W5-$R5 -> 394.20181 | Y5: =IF(ROUND(SUMIFS($L:$L,$B:$B,$B5),4)=1,"OK","REVISAR") -> OK
A6: TRE-005 | B6: IT-005 | C6: 1 | D6: CAR-001 | E6: =IFERROR(INDEX(CARGAS!$B:$B,MATCH($D6,CARGAS!$A:$A,0)),"") -> 46206 | F6: LOC-001 | G6: LOC-004 | H6: 400 | I6: MOT-001 | J6: =IFERROR($H6/SUMIFS($H:$H,$B:$B,$B6),0) -> 0.55555556 | L6: =IF($K6="",$J6,$K6) -> 0.55555556 | M6: =IFERROR(INDEX(ITENS_PEDIDO!$Q:$Q,MATCH($B6,ITENS_PEDIDO!$A:$A,0)),0) -> 1200 | N6: =$L6*$M6 -> 666.66667 | O6: =IFERROR($N6/SUMIFS($N:$N,$D:$D,$D6),0) -> 0.17068273 | P6: =SUMIFS(CUSTOS!$H:$H,CUSTOS!$D:$D,$A6,CUSTOS!$J:$J,"SIM") -> 0 | Q6: =$O6*SUMIFS(CUSTOS!$H:$H,CUSTOS!$C:$C,$D6,CUSTOS!$B:$B,"CARGA",CUSTOS!$J:$J,"SIM") -> 0 | R6: =SUMIFS(CUSTOS!$H:$H,CUSTOS!$D:$D,$A6,CUSTOS!$I:$I,"EMPRESA")+$O6*SUMIFS(CUSTOS!$H:$H,CUSTOS!$C:$C,$D6,CUSTOS!$B:$B,"CARGA",CUSTOS!$I:$I,"EMPRESA") -> 208.23293 | S6: =$N6-$P6-$Q6 -> 666.66667 | T6: =IFERROR(INDEX(MOTORISTAS!$F:$F,MATCH($I6,MOTORISTAS!$A:$A,0)),"") -> FROTA | U6: =IFERROR(INDEX(MOTORISTAS!$H:$H,MATCH($I6,MOTORISTAS!$A:$A,0)),"") -> %_FRETE | V6: =IFERROR(INDEX(MOTORISTAS!$I:$I,MATCH($I6,MOTORISTAS!$A:$A,0)),0) -> 0.12 | W6: =MAX(0,IF($U6="%_FRETE",$S6*$V6,IF($U6="R$/KM",IFERROR(INDEX(CARGAS!$I:$I,MATCH($D6,CARGAS!$A:$A,0)),0)*$V6*$O6-$P6-$Q6,IF($U6="FIXO_VEICULO",$V6-$P6-$Q6,0)))) -> 80 | X6: =$N6-$W6-$R6 -> 378.43373 | Y6: =IF(ROUND(SUMIFS($L:$L,$B:$B,$B6),4)=1,"OK","REVISAR") -> OK
A7: TRE-006 | B7: IT-006 | C7: 1 | D7: CAR-001 | E7: =IFERROR(INDEX(CARGAS!$B:$B,MATCH($D7,CARGAS!$A:$A,0)),"") -> 46206 | F7: LOC-001 | G7: LOC-004 | H7: 400 | I7: MOT-001 | J7: =IFERROR($H7/SUMIFS($H:$H,$B:$B,$B7),0) -> 0.55555556 | L7: =IF($K7="",$J7,$K7) -> 0.55555556 | M7: =IFERROR(INDEX(ITENS_PEDIDO!$Q:$Q,MATCH($B7,ITENS_PEDIDO!$A:$A,0)),0) -> 1150 | N7: =$L7*$M7 -> 638.88889 | O7: =IFERROR($N7/SUMIFS($N:$N,$D:$D,$D7),0) -> 0.16357095 | P7: =SUMIFS(CUSTOS!$H:$H,CUSTOS!$D:$D,$A7,CUSTOS!$J:$J,"SIM") -> 0 | Q7: =$O7*SUMIFS(CUSTOS!$H:$H,CUSTOS!$C:$C,$D7,CUSTOS!$B:$B,"CARGA",CUSTOS!$J:$J,"SIM") -> 0 | R7: =SUMIFS(CUSTOS!$H:$H,CUSTOS!$D:$D,$A7,CUSTOS!$I:$I,"EMPRESA")+$O7*SUMIFS(CUSTOS!$H:$H,CUSTOS!$C:$C,$D7,CUSTOS!$B:$B,"CARGA",CUSTOS!$I:$I,"EMPRESA") -> 199.55656 | S7: =$N7-$P7-$Q7 -> 638.88889 | T7: =IFERROR(INDEX(MOTORISTAS!$F:$F,MATCH($I7,MOTORISTAS!$A:$A,0)),"") -> FROTA | U7: =IFERROR(INDEX(MOTORISTAS!$H:$H,MATCH($I7,MOTORISTAS!$A:$A,0)),"") -> %_FRETE | V7: =IFERROR(INDEX(MOTORISTAS!$I:$I,MATCH($I7,MOTORISTAS!$A:$A,0)),0) -> 0.12 | W7: =MAX(0,IF($U7="%_FRETE",$S7*$V7,IF($U7="R$/KM",IFERROR(INDEX(CARGAS!$I:$I,MATCH($D7,CARGAS!$A:$A,0)),0)*$V7*$O7-$P7-$Q7,IF($U7="FIXO_VEICULO",$V7-$P7-$Q7,0)))) -> 76.666667 | X7: =$N7-$W7-$R7 -> 362.66566 | Y7: =IF(ROUND(SUMIFS($L:$L,$B:$B,$B7),4)=1,"OK","REVISAR") -> OK
A8: TRE-007 | B8: IT-001 | C8: 2 | D8: CAR-002 | E8: =IFERROR(INDEX(CARGAS!$B:$B,MATCH($D8,CARGAS!$A:$A,0)),"") -> 46207 | F8: LOC-004 | G8: LOC-002 | H8: 450 | I8: TER-001 | J8: =IFERROR($H8/SUMIFS($H:$H,$B:$B,$B8),0) -> 0.52941176 | L8: =IF($K8="",$J8,$K8) -> 0.52941176 | M8: =IFERROR(INDEX(ITENS_PEDIDO!$Q:$Q,MATCH($B8,ITENS_PEDIDO!$A:$A,0)),0) -> 1400 | N8: =$L8*$M8 -> 741.17647 | O8: =IFERROR($N8/SUMIFS($N:$N,$D:$D,$D8),0) -> 0.19795758 | P8: =SUMIFS(CUSTOS!$H:$H,CUSTOS!$D:$D,$A8,CUSTOS!$J:$J,"SIM") -> 0 | Q8: =$O8*SUMIFS(CUSTOS!$H:$H,CUSTOS!$C:$C,$D8,CUSTOS!$B:$B,"CARGA",CUSTOS!$J:$J,"SIM") -> 0 | R8: =SUMIFS(CUSTOS!$H:$H,CUSTOS!$D:$D,$A8,CUSTOS!$I:$I,"EMPRESA")+$O8*SUMIFS(CUSTOS!$H:$H,CUSTOS!$C:$C,$D8,CUSTOS!$B:$B,"CARGA",CUSTOS!$I:$I,"EMPRESA") -> 0 | S8: =$N8-$P8-$Q8 -> 741.17647 | T8: =IFERROR(INDEX(MOTORISTAS!$F:$F,MATCH($I8,MOTORISTAS!$A:$A,0)),"") -> TERCEIRO | U8: =IFERROR(INDEX(MOTORISTAS!$H:$H,MATCH($I8,MOTORISTAS!$A:$A,0)),"") -> %_FRETE | V8: =IFERROR(INDEX(MOTORISTAS!$I:$I,MATCH($I8,MOTORISTAS!$A:$A,0)),0) -> 0.7 | W8: =MAX(0,IF($U8="%_FRETE",$S8*$V8,IF($U8="R$/KM",IFERROR(INDEX(CARGAS!$I:$I,MATCH($D8,CARGAS!$A:$A,0)),0)*$V8*$O8-$P8-$Q8,IF($U8="FIXO_VEICULO",$V8-$P8-$Q8,0)))) -> 518.82353 | X8: =$N8-$W8-$R8 -> 222.35294 | Y8: =IF(ROUND(SUMIFS($L:$L,$B:$B,$B8),4)=1,"OK","REVISAR") -> OK
A9: TRE-008 | B9: IT-002 | C9: 2 | D9: CAR-002 | E9: =IFERROR(INDEX(CARGAS!$B:$B,MATCH($D9,CARGAS!$A:$A,0)),"") -> 46207 | F9: LOC-004 | G9: LOC-002 | H9: 450 | I9: TER-001 | J9: =IFERROR($H9/SUMIFS($H:$H,$B:$B,$B9),0) -> 0.52941176 | L9: =IF($K9="",$J9,$K9) -> 0.52941176 | M9: =IFERROR(INDEX(ITENS_PEDIDO!$Q:$Q,MATCH($B9,ITENS_PEDIDO!$A:$A,0)),0) -> 1350 | N9: =$L9*$M9 -> 714.70588 | O9: =IFERROR($N9/SUMIFS($N:$N,$D:$D,$D9),0) -> 0.19088767 | P9: =SUMIFS(CUSTOS!$H:$H,CUSTOS!$D:$D,$A9,CUSTOS!$J:$J,"SIM") -> 0 | Q9: =$O9*SUMIFS(CUSTOS!$H:$H,CUSTOS!$C:$C,$D9,CUSTOS!$B:$B,"CARGA",CUSTOS!$J:$J,"SIM") -> 0 | R9: =SUMIFS(CUSTOS!$H:$H,CUSTOS!$D:$D,$A9,CUSTOS!$I:$I,"EMPRESA")+$O9*SUMIFS(CUSTOS!$H:$H,CUSTOS!$C:$C,$D9,CUSTOS!$B:$B,"CARGA",CUSTOS!$I:$I,"EMPRESA") -> 0 | S9: =$N9-$P9-$Q9 -> 714.70588 | T9: =IFERROR(INDEX(MOTORISTAS!$F:$F,MATCH($I9,MOTORISTAS!$A:$A,0)),"") -> TERCEIRO | U9: =IFERROR(INDEX(MOTORISTAS!$H:$H,MATCH($I9,MOTORISTAS!$A:$A,0)),"") -> %_FRETE | V9: =IFERROR(INDEX(MOTORISTAS!$I:$I,MATCH($I9,MOTORISTAS!$A:$A,0)),0) -> 0.7 | W9: =MAX(0,IF($U9="%_FRETE",$S9*$V9,IF($U9="R$/KM",IFERROR(INDEX(CARGAS!$I:$I,MATCH($D9,CARGAS!$A:$A,0)),0)*$V9*$O9-$P9-$Q9,IF($U9="FIXO_VEICULO",$V9-$P9-$Q9,0)))) -> 500.29412 | X9: =$N9-$W9-$R9 -> 214.41176 | Y9: =IF(ROUND(SUMIFS($L:$L,$B:$B,$B9),4)=1,"OK","REVISAR") -> OK
A10: TRE-009 | B10: IT-003 | C10: 2 | D10: CAR-002 | E10: =IFERROR(INDEX(CARGAS!$B:$B,MATCH($D10,CARGAS!$A:$A,0)),"") -> 46207 | F10: LOC-004 | G10: LOC-002 | H10: 450 | I10: TER-001 | J10: =IFERROR($H10/SUMIFS($H:$H,$B:$B,$B10),0) -> 0.52941176 | L10: =IF($K10="",$J10,$K10) -> 0.52941176 | M10: =IFERROR(INDEX(ITENS_PEDIDO!$Q:$Q,MATCH($B10,ITENS_PEDIDO!$A:$A,0)),0) -> 1300 | N10: =$L10*$M10 -> 688.23529 | O10: =IFERROR($N10/SUMIFS($N:$N,$D:$D,$D10),0) -> 0.18381775 | P10: =SUMIFS(CUSTOS!$H:$H,CUSTOS!$D:$D,$A10,CUSTOS!$J:$J,"SIM") -> 0 | Q10: =$O10*SUMIFS(CUSTOS!$H:$H,CUSTOS!$C:$C,$D10,CUSTOS!$B:$B,"CARGA",CUSTOS!$J:$J,"SIM") -> 0 | R10: =SUMIFS(CUSTOS!$H:$H,CUSTOS!$D:$D,$A10,CUSTOS!$I:$I,"EMPRESA")+$O10*SUMIFS(CUSTOS!$H:$H,CUSTOS!$C:$C,$D10,CUSTOS!$B:$B,"CARGA",CUSTOS!$I:$I,"EMPRESA") -> 0 | S10: =$N10-$P10-$Q10 -> 688.23529 | T10: =IFERROR(INDEX(MOTORISTAS!$F:$F,MATCH($I10,MOTORISTAS!$A:$A,0)),"") -> TERCEIRO | U10: =IFERROR(INDEX(MOTORISTAS!$H:$H,MATCH($I10,MOTORISTAS!$A:$A,0)),"") -> %_FRETE | V10: =IFERROR(INDEX(MOTORISTAS!$I:$I,MATCH($I10,MOTORISTAS!$A:$A,0)),0) -> 0.7 | W10: =MAX(0,IF($U10="%_FRETE",$S10*$V10,IF($U10="R$/KM",IFERROR(INDEX(CARGAS!$I:$I,MATCH($D10,CARGAS!$A:$A,0)),0)*$V10*$O10-$P10-$Q10,IF($U10="FIXO_VEICULO",$V10-$P10-$Q10,0)))) -> 481.76471 | X10: =$N10-$W10-$R10 -> 206.47059 | Y10: =IF(ROUND(SUMIFS($L:$L,$B:$B,$B10),4)=1,"OK","REVISAR") -> OK
A11: TRE-010 | B11: IT-004 | C11: 2 | D11: CAR-002 | E11: =IFERROR(INDEX(CARGAS!$B:$B,MATCH($D11,CARGAS!$A:$A,0)),"") -> 46207 | F11: LOC-004 | G11: LOC-005 | H11: 320 | I11: TER-001 | J11: =IFERROR($H11/SUMIFS($H:$H,$B:$B,$B11),0) -> 0.44444444 | L11: =IF($K11="",$J11,$K11) -> 0.44444444 | M11: =IFERROR(INDEX(ITENS_PEDIDO!$Q:$Q,MATCH($B11,ITENS_PEDIDO!$A:$A,0)),0) -> 1250 | N11: =$L11*$M11 -> 555.55556 | O11: =IFERROR($N11/SUMIFS($N:$N,$D:$D,$D11),0) -> 0.1483809 | P11: =SUMIFS(CUSTOS!$H:$H,CUSTOS!$D:$D,$A11,CUSTOS!$J:$J,"SIM") -> 0 | Q11: =$O11*SUMIFS(CUSTOS!$H:$H,CUSTOS!$C:$C,$D11,CUSTOS!$B:$B,"CARGA",CUSTOS!$J:$J,"SIM") -> 0 | R11: =SUMIFS(CUSTOS!$H:$H,CUSTOS!$D:$D,$A11,CUSTOS!$I:$I,"EMPRESA")+$O11*SUMIFS(CUSTOS!$H:$H,CUSTOS!$C:$C,$D11,CUSTOS!$B:$B,"CARGA",CUSTOS!$I:$I,"EMPRESA") -> 0 | S11: =$N11-$P11-$Q11 -> 555.55556 | T11: =IFERROR(INDEX(MOTORISTAS!$F:$F,MATCH($I11,MOTORISTAS!$A:$A,0)),"") -> TERCEIRO | U11: =IFERROR(INDEX(MOTORISTAS!$H:$H,MATCH($I11,MOTORISTAS!$A:$A,0)),"") -> %_FRETE | V11: =IFERROR(INDEX(MOTORISTAS!$I:$I,MATCH($I11,MOTORISTAS!$A:$A,0)),0) -> 0.7 | W11: =MAX(0,IF($U11="%_FRETE",$S11*$V11,IF($U11="R$/KM",IFERROR(INDEX(CARGAS!$I:$I,MATCH($D11,CARGAS!$A:$A,0)),0)*$V11*$O11-$P11-$Q11,IF($U11="FIXO_VEICULO",$V11-$P11-$Q11,0)))) -> 388.88889 | X11: =$N11-$W11-$R11 -> 166.66667 | Y11: =IF(ROUND(SUMIFS($L:$L,$B:$B,$B11),4)=1,"OK","REVISAR") -> OK
A12: TRE-011 | B12: IT-005 | C12: 2 | D12: CAR-002 | E12: =IFERROR(INDEX(CARGAS!$B:$B,MATCH($D12,CARGAS!$A:$A,0)),"") -> 46207 | F12: LOC-004 | G12: LOC-005 | H12: 320 | I12: TER-001 | J12: =IFERROR($H12/SUMIFS($H:$H,$B:$B,$B12),0) -> 0.44444444 | L12: =IF($K12="",$J12,$K12) -> 0.44444444 | M12: =IFERROR(INDEX(ITENS_PEDIDO!$Q:$Q,MATCH($B12,ITENS_PEDIDO!$A:$A,0)),0) -> 1200 | N12: =$L12*$M12 -> 533.33333 | O12: =IFERROR($N12/SUMIFS($N:$N,$D:$D,$D12),0) -> 0.14244567 | P12: =SUMIFS(CUSTOS!$H:$H,CUSTOS!$D:$D,$A12,CUSTOS!$J:$J,"SIM") -> 0 | Q12: =$O12*SUMIFS(CUSTOS!$H:$H,CUSTOS!$C:$C,$D12,CUSTOS!$B:$B,"CARGA",CUSTOS!$J:$J,"SIM") -> 0 | R12: =SUMIFS(CUSTOS!$H:$H,CUSTOS!$D:$D,$A12,CUSTOS!$I:$I,"EMPRESA")+$O12*SUMIFS(CUSTOS!$H:$H,CUSTOS!$C:$C,$D12,CUSTOS!$B:$B,"CARGA",CUSTOS!$I:$I,"EMPRESA") -> 0 | S12: =$N12-$P12-$Q12 -> 533.33333 | T12: =IFERROR(INDEX(MOTORISTAS!$F:$F,MATCH($I12,MOTORISTAS!$A:$A,0)),"") -> TERCEIRO | U12: =IFERROR(INDEX(MOTORISTAS!$H:$H,MATCH($I12,MOTORISTAS!$A:$A,0)),"") -> %_FRETE | V12: =IFERROR(INDEX(MOTORISTAS!$I:$I,MATCH($I12,MOTORISTAS!$A:$A,0)),0) -> 0.7 | W12: =MAX(0,IF($U12="%_FRETE",$S12*$V12,IF($U12="R$/KM",IFERROR(INDEX(CARGAS!$I:$I,MATCH($D12,CARGAS!$A:$A,0)),0)*$V12*$O12-$P12-$Q12,IF($U12="FIXO_VEICULO",$V12-$P12-$Q12,0)))) -> 373.33333 | X12: =$N12-$W12-$R12 -> 160 | Y12: =IF(ROUND(SUMIFS($L:$L,$B:$B,$B12),4)=1,"OK","REVISAR") -> OK
A13: TRE-012 | B13: IT-006 | C13: 2 | D13: CAR-002 | E13: =IFERROR(INDEX(CARGAS!$B:$B,MATCH($D13,CARGAS!$A:$A,0)),"") -> 46207 | F13: LOC-004 | G13: LOC-005 | H13: 320 | I13: TER-001 | J13: =IFERROR($H13/SUMIFS($H:$H,$B:$B,$B13),0) -> 0.44444444 | L13: =IF($K13="",$J13,$K13) -> 0.44444444 | M13: =IFERROR(INDEX(ITENS_PEDIDO!$Q:$Q,MATCH($B13,ITENS_PEDIDO!$A:$A,0)),0) -> 1150 | N13: =$L13*$M13 -> 511.11111 | O13: =IFERROR($N13/SUMIFS($N:$N,$D:$D,$D13),0) -> 0.13651043 | P13: =SUMIFS(CUSTOS!$H:$H,CUSTOS!$D:$D,$A13,CUSTOS!$J:$J,"SIM") -> 0 | Q13: =$O13*SUMIFS(CUSTOS!$H:$H,CUSTOS!$C:$C,$D13,CUSTOS!$B:$B,"CARGA",CUSTOS!$J:$J,"SIM") -> 0 | R13: =SUMIFS(CUSTOS!$H:$H,CUSTOS!$D:$D,$A13,CUSTOS!$I:$I,"EMPRESA")+$O13*SUMIFS(CUSTOS!$H:$H,CUSTOS!$C:$C,$D13,CUSTOS!$B:$B,"CARGA",CUSTOS!$I:$I,"EMPRESA") -> 0 | S13: =$N13-$P13-$Q13 -> 511.11111 | T13: =IFERROR(INDEX(MOTORISTAS!$F:$F,MATCH($I13,MOTORISTAS!$A:$A,0)),"") -> TERCEIRO | U13: =IFERROR(INDEX(MOTORISTAS!$H:$H,MATCH($I13,MOTORISTAS!$A:$A,0)),"") -> %_FRETE | V13: =IFERROR(INDEX(MOTORISTAS!$I:$I,MATCH($I13,MOTORISTAS!$A:$A,0)),0) -> 0.7 | W13: =MAX(0,IF($U13="%_FRETE",$S13*$V13,IF($U13="R$/KM",IFERROR(INDEX(CARGAS!$I:$I,MATCH($D13,CARGAS!$A:$A,0)),0)*$V13*$O13-$P13-$Q13,IF($U13="FIXO_VEICULO",$V13-$P13-$Q13,0)))) -> 357.77778 | X13: =$N13-$W13-$R13 -> 153.33333 | Y13: =IF(ROUND(SUMIFS($L:$L,$B:$B,$B13),4)=1,"OK","REVISAR") -> OK
... A19: TRE-018 | B19: IT-012 | C19: 1 | D19: CAR-005 | E19: =IFERROR(INDEX(CARGAS!$B:$B,MATCH($D19,CARGAS!$A:$A,0)),"") -> 46216 | F19: LOC-003 | G19: LOC-005 | H19: 460 | I19: TER-002 | J19: =IFERROR($H19/SUMIFS($H:$H,$B:$B,$B19),0) -> 1 | L19: =IF($K19="",$J19,$K19) -> 1 | M19: =IFERROR(INDEX(ITENS_PEDIDO!$Q:$Q,MATCH($B19,ITENS_PEDIDO!$A:$A,0)),0) -> 750 | N19: =$L19*$M19 -> 750 | O19: =IFERROR($N19/SUMIFS($N:$N,$D:$D,$D19),0) -> 1 | P19: =SUMIFS(CUSTOS!$H:$H,CUSTOS!$D:$D,$A19,CUSTOS!$J:$J,"SIM") -> 0 | Q19: =$O19*SUMIFS(CUSTOS!$H:$H,CUSTOS!$C:$C,$D19,CUSTOS!$B:$B,"CARGA",CUSTOS!$J:$J,"SIM") -> 0 | R19: =SUMIFS(CUSTOS!$H:$H,CUSTOS!$D:$D,$A19,CUSTOS!$I:$I,"EMPRESA")+$O19*SUMIFS(CUSTOS!$H:$H,CUSTOS!$C:$C,$D19,CUSTOS!$B:$B,"CARGA",CUSTOS!$I:$I,"EMPRESA") -> 0 | S19: =$N19-$P19-$Q19 -> 750 | T19: =IFERROR(INDEX(MOTORISTAS!$F:$F,MATCH($I19,MOTORISTAS!$A:$A,0)),"") -> TERCEIRO | U19: =IFERROR(INDEX(MOTORISTAS!$H:$H,MATCH($I19,MOTORISTAS!$A:$A,0)),"") -> FIXO_VEICULO | V19: =IFERROR(INDEX(MOTORISTAS!$I:$I,MATCH($I19,MOTORISTAS!$A:$A,0)),0) -> 320 | W19: =MAX(0,IF($U19="%_FRETE",$S19*$V19,IF($U19="R$/KM",IFERROR(INDEX(CARGAS!$I:$I,MATCH($D19,CARGAS!$A:$A,0)),0)*$V19*$O19-$P19-$Q19,IF($U19="FIXO_VEICULO",$V19-$P19-$Q19,0)))) -> 320 | X19: =$N19-$W19-$R19 -> 430 | Y19: =IF(ROUND(SUMIFS($L:$L,$B:$B,$B19),4)=1,"OK","REVISAR") -> OK
B21: RECEITA_TRECHO = frete do veículo × peso (km). PART_NA_CARGA = participação do veículo na receita daquela carga (é por ela que se rateia pedágio, combustível e pagamento por km).
B22: BASE_CALCULO = receita − custos dedutíveis. REMUNERAÇÃO: %_FRETE incide sobre a base; R$/KM paga (km da CARGA × R$/km) rateado entre os veículos; FIXO_VEICULO paga por carro. MARGEM = receita − remuneração − custos da empresa.

Sheet CUSTOS
A1: ID_CUSTO | B1: NIVEL | C1: ID_CARGA | D1: ID_TRECHO | E1: DATA | F1: TIPO | G1: DESCRICAO | H1: VALOR | I1: PAGO_POR | J1: DEDUZ_BASE | K1: COMPROVANTE
A2: CUS-001 | B2: CARGA | C2: CAR-001 | E2: 46206 | F2: PEDAGIO | G2: Pedágios Campinas → Registro | H2: 240 | I2: EMPRESA | J2: NAO | K2: TAG-0031
A3: CUS-002 | B3: CARGA | C3: CAR-001 | E3: 46206 | F3: COMBUSTIVEL | G3: Abastecimento cegonha CEG-002 | H3: 980 | I3: EMPRESA | J3: NAO | K3: NF-11220
A4: CUS-003 | B4: CARGA | C4: CAR-003 | E4: 46211 | F4: PEDAGIO | G4: Pedágios Curitiba → Cascavel | H4: 150 | I4: EMPRESA | J4: NAO | K4: TAG-0032
A5: CUS-004 | B5: CARGA | C5: CAR-003 | E5: 46211 | F5: COMBUSTIVEL | G5: Abastecimento cegonha CEG-001 | H5: 620 | I5: EMPRESA | J5: NAO | K5: NF-11245
A6: CUS-005 | B6: CARGA | C6: CAR-004 | E6: 46212 | F6: ADIANTAMENTO | G6: Pedágio + diesel adiantados ao agregado (desconta dele) | H6: 480 | I6: EMPRESA | J6: SIM | K6: TAG-0033
A7: CUS-006 | B7: TRECHO | C7: CAR-004 | D7: TRE-016 | E7: 46212 | F7: ESTADIA | G7: 3h de espera no pátio (culpa do cliente — repassar) | H7: 150 | I7: EMPRESA | J7: NAO | K7: REC-0087
B9: NIVEL=CARGA → rateado entre os veículos da carga na proporção da receita. NIVEL=TRECHO → lançado direto naquele veículo. DEDUZ_BASE=SIM desconta do executante; NAO é custo da empresa. Custo de terceiro que ele mesmo banca não se lança aqui.

Sheet CHECKLIST
A1: ID_CHECKLIST | B1: ID_ITEM | C1: ID_TRECHO | D1: ID_CARGA | E1: ETAPA | F1: DATA_HORA | G1: RESPONSAVEL | H1: KM_VEICULO | I1: COMBUSTIVEL | J1: AVARIAS_IDENTIFICADAS | K1: LINK_FOTOS | L1: ASSINATURA_RECEBEDOR | M1: STATUS
A2: CHK-001 | B2: IT-001 | C2: TRE-001 | D2: CAR-001 | E2: COLETA | F2: 46206.354 | G2: João Pereira | H2: 48210 | I2: 1/4 | J2: Risco leve porta traseira esquerda (preexistente) | K2: fotos/IT-001-col | L2: Pátio Beta | M2: CONCLUIDO
A3: CHK-002 | B3: IT-001 | C3: TRE-001 | D3: CAR-001 | E3: TRANSBORDO | F3: 46207.458 | G3: João Pereira / Cegonha Sul | H3: 48215 | I3: 1/4 | J3: Sem avaria nova. Para-choque íntegro. | K3: fotos/IT-001-tra | L3: Cegonha Sul | M3: CONCLUIDO
A4: CHK-003 | B4: IT-001 | C4: TRE-007 | D4: CAR-002 | E4: ENTREGA | F4: 46209.632 | G4: Cegonha Sul | H4: 48219 | I4: 1/4 | J4: Para-choque traseiro riscado — AVARIA NOVA | K4: fotos/IT-001-ent | L4: Marcos Silva | M4: CONCLUIDO
A5: CHK-004 | B5: IT-010 | C5: TRE-016 | D5: CAR-004 | E5: COLETA | F5: 46212.375 | G5: Anderson Rocha | H5: 31450 | I5: 1/2 | J5: Retrovisor direito trincado (preexistente) | K5: fotos/IT-010-col | L5: Marcos Silva | M5: CONCLUIDO
B7: O checklist de TRANSBORDO é o que resolve a pergunta 'de quem é a avaria': comparando TRANSBORDO com ENTREGA, a avaria do IT-001 apareceu no trecho do terceiro. Sem esse registro fotográfico, a responsabilidade é indefensável.

Sheet OCORRENCIAS
A1: ID_OCORRENCIA | B1: DATA | C1: ID_ITEM | D1: ID_TRECHO | E1: ID_CARGA | F1: ID_CLIENTE | G1: ID_EXECUTANTE | H1: TIPO | I1: DESCRICAO | J1: APONTADO_POR | K1: CUSTO | L1: RESPONSABILIDADE | M1: STATUS | N1: ACAO_TOMADA
A2: OCO-001 | B2: 46209 | C2: IT-001 | D2: TRE-007 | E2: CAR-002 | F2: CLI-001 | G2: TER-001 | H2: AVARIA | I2: Para-choque traseiro riscado. Checklist de transbordo comprova que saiu íntegro de Registro. | J2: Logística | K2: 850 | L2: EXECUTANTE | M2: APROVADA | N2: Indenizado ao cliente; descontado do terceiro no acerto
A3: OCO-002 | B3: 46212 | C3: IT-010 | D3: TRE-016 | E3: CAR-004 | F3: CLI-002 | G3: MOT-003 | H3: ESTADIA | I3: Veículo não liberado no pátio no horário agendado (3h de espera) | J3: Anderson Rocha | K3: 150 | L3: CLIENTE | M3: EM_ANALISE | N3: Repassar estadia ao cliente
B5: RESPONSABILIDADE = EXECUTANTE + STATUS = APROVADA → vira desconto no acerto do período (aba FATURAMENTO_MOTORISTA). Enquanto está EM_ANALISE, não desconta ninguém. Regra de avaria em transbordo ainda a definir com o cliente.

Sheet HISTORICO_LOG
A1: DATA_HORA | B1: USUARIO | C1: ENTIDADE | D1: ID_REGISTRO | E1: CAMPO | F1: DE | G1: PARA | H1: MOTIVO
A2: 46205.425 | B2: Ana (Comercial) | C2: ITENS_PEDIDO | D2: IT-001 | E2: VALOR_FRETE | F2: 1300 | G2: 1400 | H2: Reajuste aprovado pelo cliente
A3: 46205.611 | B3: Paula (Logística) | C3: CARGAS | D3: CAR-001 | E3: ID_MOTORISTA | F3: MOT-002 | G3: MOT-001 | H3: Troca de escala
A4: 46207.337 | B4: Paula (Logística) | C4: TRECHOS | D4: TRE-007 | E4: ID_EXECUTANTE | F4: MOT-001 | G4: TER-001 | H4: Transbordo em Registro
B6: Repare no IT-007: o frete mudou de 600 para 620 e NÃO existe log. A coluna CONTROLE_FRETE (ITENS_PEDIDO) acusa 'BLOQUEAR: SEM LOG'. Em planilha isso é uma trava visual; em sistema, o campo simplesmente não salva sem justificativa.

Sheet FATURAMENTO_MOTORISTA
A1: ACERTO POR MOTORISTA / TERCEIRO — base líquida (frete menos custo)
A2: Período (editar em PARAMETROS): | C2: =PARAMETROS!B3 -> 46204 | D2: =PARAMETROS!B4 -> 46234
A4: ID_EXECUTANTE | B4: NOME | C4: VINCULO | D4: REGRA | E4: PARAMETRO | F4: QTDE_TRECHOS | G4: KM_RODADOS | H4: RECEITA_ATRIBUIDA | I4: CUSTOS_DEDUZIDOS | J4: BASE_CALCULO | K4: REMUNERACAO | L4: DESCONTO_OCORRENCIAS | M4: LIQUIDO_A_RECEBER | N4: % SOBRE RECEITA
A5: MOT-001 | B5: =IFERROR(INDEX(MOTORISTAS!$B:$B,MATCH($A5,MOTORISTAS!$A:$A,0)),"") -> João Pereira | C5: =IFERROR(INDEX(MOTORISTAS!$F:$F,MATCH($A5,MOTORISTAS!$A:$A,0)),"") -> FROTA | D5: =IFERROR(INDEX(MOTORISTAS!$H:$H,MATCH($A5,MOTORISTAS!$A:$A,0)),"") -> %_FRETE | E5: =IFERROR(INDEX(MOTORISTAS!$I:$I,MATCH($A5,MOTORISTAS!$A:$A,0)),0) -> 0.12 | F5: =COUNTIFS(TRECHOS!$I:$I,$A5,TRECHOS!$E:$E,">="&PARAMETROS!$B$3,TRECHOS!$E:$E,"<="&PARAMETROS!$B$4) -> 6 | G5: =SUMIFS(TRECHOS!$H:$H,TRECHOS!$I:$I,$A5,TRECHOS!$E:$E,">="&PARAMETROS!$B$3,TRECHOS!$E:$E,"<="&PARAMETROS!$B$4) -> 2400 | H5: =SUMIFS(TRECHOS!$N:$N,TRECHOS!$I:$I,$A5,TRECHOS!$E:$E,">="&PARAMETROS!$B$3,TRECHOS!$E:$E,"<="&PARAMETROS!$B$4) -> 3905.8824 | I5: =SUMIFS(TRECHOS!$P:$P,TRECHOS!$I:$I,$A5,TRECHOS!$E:$E,">="&PARAMETROS!$B$3,TRECHOS!$E:$E,"<="&PARAMETROS!$B$4)+SUMIFS(TRECHOS!$Q:$Q,TRECHOS!$I:$I,$A5,TRECHOS!$E:$E,">="&PARAMETROS!$B$3,TRECHOS!$E:$E,"<="&PARAMETROS!$B$4) -> 0 | J5: =SUMIFS(TRECHOS!$S:$S,TRECHOS!$I:$I,$A5,TRECHOS!$E:$E,">="&PARAMETROS!$B$3,TRECHOS!$E:$E,"<="&PARAMETROS!$B$4) -> 3905.8824 | K5: =SUMIFS(TRECHOS!$W:$W,TRECHOS!$I:$I,$A5,TRECHOS!$E:$E,">="&PARAMETROS!$B$3,TRECHOS!$E:$E,"<="&PARAMETROS!$B$4) -> 468.70588 | L5: =SUMIFS(OCORRENCIAS!$K:$K,OCORRENCIAS!$G:$G,$A5,OCORRENCIAS!$L:$L,"EXECUTANTE",OCORRENCIAS!$M:$M,"APROVADA",OCORRENCIAS!$B:$B,">="&PARAMETROS!$B$3,OCORRENCIAS!$B:$B,"<="&PARAMETROS!$B$4) -> 0 | M5: =MAX(0,$K5-$L5) -> 468.70588 | N5: =IFERROR($M5/$H5,0) -> 0.12
A6: MOT-002 | B6: =IFERROR(INDEX(MOTORISTAS!$B:$B,MATCH($A6,MOTORISTAS!$A:$A,0)),"") -> Carlos Amaral | C6: =IFERROR(INDEX(MOTORISTAS!$F:$F,MATCH($A6,MOTORISTAS!$A:$A,0)),"") -> FROTA | D6: =IFERROR(INDEX(MOTORISTAS!$H:$H,MATCH($A6,MOTORISTAS!$A:$A,0)),"") -> R$/KM | E6: =IFERROR(INDEX(MOTORISTAS!$I:$I,MATCH($A6,MOTORISTAS!$A:$A,0)),0) -> 1.1 | F6: =COUNTIFS(TRECHOS!$I:$I,$A6,TRECHOS!$E:$E,">="&PARAMETROS!$B$3,TRECHOS!$E:$E,"<="&PARAMETROS!$B$4) -> 3 | G6: =SUMIFS(TRECHOS!$H:$H,TRECHOS!$I:$I,$A6,TRECHOS!$E:$E,">="&PARAMETROS!$B$3,TRECHOS!$E:$E,"<="&PARAMETROS!$B$4) -> 1500 | H6: =SUMIFS(TRECHOS!$N:$N,TRECHOS!$I:$I,$A6,TRECHOS!$E:$E,">="&PARAMETROS!$B$3,TRECHOS!$E:$E,"<="&PARAMETROS!$B$4) -> 2000 | I6: =SUMIFS(TRECHOS!$P:$P,TRECHOS!$I:$I,$A6,TRECHOS!$E:$E,">="&PARAMETROS!$B$3,TRECHOS!$E:$E,"<="&PARAMETROS!$B$4)+SUMIFS(TRECHOS!$Q:$Q,TRECHOS!$I:$I,$A6,TRECHOS!$E:$E,">="&PARAMETROS!$B$3,TRECHOS!$E:$E,"<="&PARAMETROS!$B$4) -> 0 | J6: =SUMIFS(TRECHOS!$S:$S,TRECHOS!$I:$I,$A6,TRECHOS!$E:$E,">="&PARAMETROS!$B$3,TRECHOS!$E:$E,"<="&PARAMETROS!$B$4) -> 2000 | K6: =SUMIFS(TRECHOS!$W:$W,TRECHOS!$I:$I,$A6,TRECHOS!$E:$E,">="&PARAMETROS!$B$3,TRECHOS!$E:$E,"<="&PARAMETROS!$B$4) -> 550 | L6: =SUMIFS(OCORRENCIAS!$K:$K,OCORRENCIAS!$G:$G,$A6,OCORRENCIAS!$L:$L,"EXECUTANTE",OCORRENCIAS!$M:$M,"APROVADA",OCORRENCIAS!$B:$B,">="&PARAMETROS!$B$3,OCORRENCIAS!$B:$B,"<="&PARAMETROS!$B$4) -> 0 | M6: =MAX(0,$K6-$L6) -> 550 | N6: =IFERROR($M6/$H6,0) -> 0.275
A7: MOT-003 | B7: =IFERROR(INDEX(MOTORISTAS!$B:$B,MATCH($A7,MOTORISTAS!$A:$A,0)),"") -> Anderson Rocha | C7: =IFERROR(INDEX(MOTORISTAS!$F:$F,MATCH($A7,MOTORISTAS!$A:$A,0)),"") -> AGREGADO | D7: =IFERROR(INDEX(MOTORISTAS!$H:$H,MATCH($A7,MOTORISTAS!$A:$A,0)),"") -> %_FRETE | E7: =IFERROR(INDEX(MOTORISTAS!$I:$I,MATCH($A7,MOTORISTAS!$A:$A,0)),0) -> 0.65 | F7: =COUNTIFS(TRECHOS!$I:$I,$A7,TRECHOS!$E:$E,">="&PARAMETROS!$B$3,TRECHOS!$E:$E,"<="&PARAMETROS!$B$4) -> 2 | G7: =SUMIFS(TRECHOS!$H:$H,TRECHOS!$I:$I,$A7,TRECHOS!$E:$E,">="&PARAMETROS!$B$3,TRECHOS!$E:$E,"<="&PARAMETROS!$B$4) -> 920 | H7: =SUMIFS(TRECHOS!$N:$N,TRECHOS!$I:$I,$A7,TRECHOS!$E:$E,">="&PARAMETROS!$B$3,TRECHOS!$E:$E,"<="&PARAMETROS!$B$4) -> 1550 | I7: =SUMIFS(TRECHOS!$P:$P,TRECHOS!$I:$I,$A7,TRECHOS!$E:$E,">="&PARAMETROS!$B$3,TRECHOS!$E:$E,"<="&PARAMETROS!$B$4)+SUMIFS(TRECHOS!$Q:$Q,TRECHOS!$I:$I,$A7,TRECHOS!$E:$E,">="&PARAMETROS!$B$3,TRECHOS!$E:$E,"<="&PARAMETROS!$B$4) -> 480 | J7: =SUMIFS(TRECHOS!$S:$S,TRECHOS!$I:$I,$A7,TRECHOS!$E:$E,">="&PARAMETROS!$B$3,TRECHOS!$E:$E,"<="&PARAMETROS!$B$4) -> 1070 | K7: =SUMIFS(TRECHOS!$W:$W,TRECHOS!$I:$I,$A7,TRECHOS!$E:$E,">="&PARAMETROS!$B$3,TRECHOS!$E:$E,"<="&PARAMETROS!$B$4) -> 695.5 | L7: =SUMIFS(OCORRENCIAS!$K:$K,OCORRENCIAS!$G:$G,$A7,OCORRENCIAS!$L:$L,"EXECUTANTE",OCORRENCIAS!$M:$M,"APROVADA",OCORRENCIAS!$B:$B,">="&PARAMETROS!$B$3,OCORRENCIAS!$B:$B,"<="&PARAMETROS!$B$4) -> 0 | M7: =MAX(0,$K7-$L7) -> 695.5 | N7: =IFERROR($M7/$H7,0) -> 0.44870968
A8: TER-001 | B8: =IFERROR(INDEX(MOTORISTAS!$B:$B,MATCH($A8,MOTORISTAS!$A:$A,0)),"") -> Cegonha Sul Transportes | C8: =IFERROR(INDEX(MOTORISTAS!$F:$F,MATCH($A8,MOTORISTAS!$A:$A,0)),"") -> TERCEIRO | D8: =IFERROR(INDEX(MOTORISTAS!$H:$H,MATCH($A8,MOTORISTAS!$A:$A,0)),"") -> %_FRETE | E8: =IFERROR(INDEX(MOTORISTAS!$I:$I,MATCH($A8,MOTORISTAS!$A:$A,0)),0) -> 0.7 | F8: =COUNTIFS(TRECHOS!$I:$I,$A8,TRECHOS!$E:$E,">="&PARAMETROS!$B$3,TRECHOS!$E:$E,"<="&PARAMETROS!$B$4) -> 6 | G8: =SUMIFS(TRECHOS!$H:$H,TRECHOS!$I:$I,$A8,TRECHOS!$E:$E,">="&PARAMETROS!$B$3,TRECHOS!$E:$E,"<="&PARAMETROS!$B$4) -> 2310 | H8: =SUMIFS(TRECHOS!$N:$N,TRECHOS!$I:$I,$A8,TRECHOS!$E:$E,">="&PARAMETROS!$B$3,TRECHOS!$E:$E,"<="&PARAMETROS!$B$4) -> 3744.1176 | I8: =SUMIFS(TRECHOS!$P:$P,TRECHOS!$I:$I,$A8,TRECHOS!$E:$E,">="&PARAMETROS!$B$3,TRECHOS!$E:$E,"<="&PARAMETROS!$B$4)+SUMIFS(TRECHOS!$Q:$Q,TRECHOS!$I:$I,$A8,TRECHOS!$E:$E,">="&PARAMETROS!$B$3,TRECHOS!$E:$E,"<="&PARAMETROS!$B$4) -> 0 | J8: =SUMIFS(TRECHOS!$S:$S,TRECHOS!$I:$I,$A8,TRECHOS!$E:$E,">="&PARAMETROS!$B$3,TRECHOS!$E:$E,"<="&PARAMETROS!$B$4) -> 3744.1176 | K8: =SUMIFS(TRECHOS!$W:$W,TRECHOS!$I:$I,$A8,TRECHOS!$E:$E,">="&PARAMETROS!$B$3,TRECHOS!$E:$E,"<="&PARAMETROS!$B$4) -> 2620.8824 | L8: =SUMIFS(OCORRENCIAS!$K:$K,OCORRENCIAS!$G:$G,$A8,OCORRENCIAS!$L:$L,"EXECUTANTE",OCORRENCIAS!$M:$M,"APROVADA",OCORRENCIAS!$B:$B,">="&PARAMETROS!$B$3,OCORRENCIAS!$B:$B,"<="&PARAMETROS!$B$4) -> 850 | M8: =MAX(0,$K8-$L8) -> 1770.8824 | N8: =IFERROR($M8/$H8,0) -> 0.47297722
A9: TER-002 | B9: =IFERROR(INDEX(MOTORISTAS!$B:$B,MATCH($A9,MOTORISTAS!$A:$A,0)),"") -> Rodo Leste Cegonhas | C9: =IFERROR(INDEX(MOTORISTAS!$F:$F,MATCH($A9,MOTORISTAS!$A:$A,0)),"") -> TERCEIRO | D9: =IFERROR(INDEX(MOTORISTAS!$H:$H,MATCH($A9,MOTORISTAS!$A:$A,0)),"") -> FIXO_VEICULO | E9: =IFERROR(INDEX(MOTORISTAS!$I:$I,MATCH($A9,MOTORISTAS!$A:$A,0)),0) -> 320 | F9: =COUNTIFS(TRECHOS!$I:$I,$A9,TRECHOS!$E:$E,">="&PARAMETROS!$B$3,TRECHOS!$E:$E,"<="&PARAMETROS!$B$4) -> 1 | G9: =SUMIFS(TRECHOS!$H:$H,TRECHOS!$I:$I,$A9,TRECHOS!$E:$E,">="&PARAMETROS!$B$3,TRECHOS!$E:$E,"<="&PARAMETROS!$B$4) -> 460 | H9: =SUMIFS(TRECHOS!$N:$N,TRECHOS!$I:$I,$A9,TRECHOS!$E:$E,">="&PARAMETROS!$B$3,TRECHOS!$E:$E,"<="&PARAMETROS!$B$4) -> 750 | I9: =SUMIFS(TRECHOS!$P:$P,TRECHOS!$I:$I,$A9,TRECHOS!$E:$E,">="&PARAMETROS!$B$3,TRECHOS!$E:$E,"<="&PARAMETROS!$B$4)+SUMIFS(TRECHOS!$Q:$Q,TRECHOS!$I:$I,$A9,TRECHOS!$E:$E,">="&PARAMETROS!$B$3,TRECHOS!$E:$E,"<="&PARAMETROS!$B$4) -> 0 | J9: =SUMIFS(TRECHOS!$S:$S,TRECHOS!$I:$I,$A9,TRECHOS!$E:$E,">="&PARAMETROS!$B$3,TRECHOS!$E:$E,"<="&PARAMETROS!$B$4) -> 750 | K9: =SUMIFS(TRECHOS!$W:$W,TRECHOS!$I:$I,$A9,TRECHOS!$E:$E,">="&PARAMETROS!$B$3,TRECHOS!$E:$E,"<="&PARAMETROS!$B$4) -> 320 | L9: =SUMIFS(OCORRENCIAS!$K:$K,OCORRENCIAS!$G:$G,$A9,OCORRENCIAS!$L:$L,"EXECUTANTE",OCORRENCIAS!$M:$M,"APROVADA",OCORRENCIAS!$B:$B,">="&PARAMETROS!$B$3,OCORRENCIAS!$B:$B,"<="&PARAMETROS!$B$4) -> 0 | M9: =MAX(0,$K9-$L9) -> 320 | N9: =IFERROR($M9/$H9,0) -> 0.42666667
B10: TOTAL | F10: =SUM(F5:F9) -> 18 | G10: =SUM(G5:G9) -> 7590 | H10: =SUM(H5:H9) -> 11950 | I10: =SUM(I5:I9) -> 480 | J10: =SUM(J5:J9) -> 11470 | K10: =SUM(K5:K9) -> 4655.0882 | L10: =SUM(L5:L9) -> 850 | M10: =SUM(M5:M9) -> 3805.0882
B12: LIQUIDO_A_RECEBER = remuneração dos trechos do período − descontos de ocorrência aprovados. É este o valor do acerto.

Sheet PAINEL
A1: PAINEL DE ROTA, MOTORISTA E RESULTADO
A3: Veículos aguardando roteirização | B3: =COUNTIFS(ITENS_PEDIDO!$S:$S,"AGUARDANDO_ROTA") -> 1 | C3: Fila do comercial que a logística ainda não fechou
A4: Veículos com rota confirmada (a coletar) | B4: =COUNTIFS(ITENS_PEDIDO!$S:$S,"ROTA_CONFIRMADA") -> 1 | C4: Gatilho do lembrete ao comercial: carro tem que estar no local
A5: Veículos coletados / em trânsito | B5: =COUNTIFS(ITENS_PEDIDO!$S:$S,"COLETADO")+COUNTIFS(ITENS_PEDIDO!$S:$S,"EM_TRANSITO") -> 5 | C5: Carga viva na estrada
A6: Veículos entregues no período | B6: =COUNTIFS(ITENS_PEDIDO!$X:$X,">="&PARAMETROS!$B$3,ITENS_PEDIDO!$X:$X,"<="&PARAMETROS!$B$4) -> 6
A7: Entregas atrasadas (previsão vencida) | B7: =SUMPRODUCT((ITENS_PEDIDO!$W$2:$W$500<>"")*(ITENS_PEDIDO!$W$2:$W$500<TODAY())*(ITENS_PEDIDO!$X$2:$X$500="")) -> 5 | C7: Indicador de prazo (OTD)
A9: Receita de frete (veículos entregues) | B9: =SUMIFS(ITENS_PEDIDO!$Q:$Q,ITENS_PEDIDO!$S:$S,"ENTREGUE") -> 7650
A10: Remuneração de motoristas e terceiros | B10: =SUM(TRECHOS!$W:$W) -> 4655.0882 | C10: Sai do rateio por km, sobre base líquida
A11: Custos operacionais pagos pela empresa | B11: =SUM(TRECHOS!$R:$R) -> 2620 | C11: Pedágio, combustível, estadia (aba CUSTOS)
A12: Seguro estimado da carteira | B12: =SUM(ITENS_PEDIDO!$Y:$Y) -> 433.5 | C12: Valor segurado (FIPE) × taxa dos PARÂMETROS
A13: Margem bruta dos veículos | B13: =SUM(ITENS_PEDIDO!$AB:$AB) -> 5741.4118 | C13: Frete − executantes − custos − seguro
A15: Veículos com rateio inconsistente | B15: =COUNTIFS(ITENS_PEDIDO!$AC:$AC,"REVISAR") -> 0 | C15: Trava: soma dos trechos ≠ 100%
A16: Fretes alterados SEM log (bloquear) | B16: =COUNTIFS(ITENS_PEDIDO!$AD:$AD,"BLOQUEAR: SEM LOG") -> 1 | C16: Ninguém altera frete sem justificativa
A17: Ocorrências em análise | B17: =COUNTIFS(OCORRENCIAS!$M:$M,"EM_ANALISE") -> 1
A18: Custo de ocorrências no período | B18: =SUMIFS(OCORRENCIAS!$K:$K,OCORRENCIAS!$B:$B,">="&PARAMETROS!$B$3,OCORRENCIAS!$B:$B,"<="&PARAMETROS!$B$4) -> 1000

Sheet ROMANEIO
A1: ROMANEIO DE COLETA E ENTREGA
A2: Carga: | B2: CAR-002
A3: Data programada | B3: =IFERROR(INDEX(CARGAS!$B:$B,MATCH($B$2,CARGAS!$A:$A,0)),"") -> 46207
A4: Rota | B4: =IFERROR(INDEX(CARGAS!$C:$C,MATCH($B$2,CARGAS!$A:$A,0)),"") -> Registro/SP → Cascavel e Maringá/PR
A5: Cegonha | B5: =IFERROR(INDEX(CARGAS!$D:$D,MATCH($B$2,CARGAS!$A:$A,0)),"") -> CEG-003
A6: Motorista / Terceiro | B6: =IFERROR(INDEX(MOTORISTAS!$B:$B,MATCH(INDEX(CARGAS!$E:$E,MATCH($B$2,CARGAS!$A:$A,0)),MOTORISTAS!$A:$A,0)),"") -> Cegonha Sul Transportes
A7: Qtde de veículos | B7: =COUNTIFS(TRECHOS!$D:$D,$B$2) -> 6
A8: Receita da carga | B8: =SUMIFS(TRECHOS!$N:$N,TRECHOS!$D:$D,$B$2) -> 3744.1176
A10: NA CARGA? | B10: MODELO | C10: PLACA | D10: ID_ITEM | E10: ORIGEM DO TRECHO | F10: DESTINO DO TRECHO | G10: ENDEREÇO DE ENTREGA | H10: KM
A11: =IF(TRECHOS!$D2=$B$2,"SIM","-") -> - | B11: =IFERROR(INDEX(ITENS_PEDIDO!$F:$F,MATCH(TRECHOS!$B2,ITENS_PEDIDO!$A:$A,0)),"") -> Compacto 1.0 | C11: =IFERROR(INDEX(ITENS_PEDIDO!$D:$D,MATCH(TRECHOS!$B2,ITENS_PEDIDO!$A:$A,0)),"") -> ABC-1111 | D11: =TRECHOS!$B2 -> IT-001 | E11: =IFERROR(INDEX(LOCAIS!$B:$B,MATCH(TRECHOS!$F2,LOCAIS!$A:$A,0)),"") -> Pátio Beta Seminovos Campinas | F11: =IFERROR(INDEX(LOCAIS!$B:$B,MATCH(TRECHOS!$G2,LOCAIS!$A:$A,0)),"") -> Transbordo Registro | G11: =IFERROR(INDEX(LOCAIS!$D:$D,MATCH(TRECHOS!$G2,LOCAIS!$A:$A,0))&" - "&INDEX(LOCAIS!$E:$E,MATCH(TRECHOS!$G2,LOCAIS!$A:$A,0))&"/"&INDEX(LOCAIS!$F:$F,MATCH(TRECHOS!$G2,LOCAIS!$A:$A,0)),"") -> BR-116, km 440 - Registro/SP | H11: =TRECHOS!$H2 -> 400
A12: =IF(TRECHOS!$D3=$B$2,"SIM","-") -> - | B12: =IFERROR(INDEX(ITENS_PEDIDO!$F:$F,MATCH(TRECHOS!$B3,ITENS_PEDIDO!$A:$A,0)),"") -> SUV 2.0 | C12: =IFERROR(INDEX(ITENS_PEDIDO!$D:$D,MATCH(TRECHOS!$B3,ITENS_PEDIDO!$A:$A,0)),"") -> DEF-2222 | D12: =TRECHOS!$B3 -> IT-002 | E12: =IFERROR(INDEX(LOCAIS!$B:$B,MATCH(TRECHOS!$F3,LOCAIS!$A:$A,0)),"") -> Pátio Beta Seminovos Campinas | F12: =IFERROR(INDEX(LOCAIS!$B:$B,MATCH(TRECHOS!$G3,LOCAIS!$A:$A,0)),"") -> Transbordo Registro | G12: =IFERROR(INDEX(LOCAIS!$D:$D,MATCH(TRECHOS!$G3,LOCAIS!$A:$A,0))&" - "&INDEX(LOCAIS!$E:$E,MATCH(TRECHOS!$G3,LOCAIS!$A:$A,0))&"/"&INDEX(LOCAIS!$F:$F,MATCH(TRECHOS!$G3,LOCAIS!$A:$A,0)),"") -> BR-116, km 440 - Registro/SP | H12: =TRECHOS!$H3 -> 400
A13: =IF(TRECHOS!$D4=$B$2,"SIM","-") -> - | B13: =IFERROR(INDEX(ITENS_PEDIDO!$F:$F,MATCH(TRECHOS!$B4,ITENS_PEDIDO!$A:$A,0)),"") -> Hatch 1.6 | C13: =IFERROR(INDEX(ITENS_PEDIDO!$D:$D,MATCH(TRECHOS!$B4,ITENS_PEDIDO!$A:$A,0)),"") -> GHI-3333 | D13: =TRECHOS!$B4 -> IT-003 | E13: =IFERROR(INDEX(LOCAIS!$B:$B,MATCH(TRECHOS!$F4,LOCAIS!$A:$A,0)),"") -> Pátio Beta Seminovos Campinas | F13: =IFERROR(INDEX(LOCAIS!$B:$B,MATCH(TRECHOS!$G4,LOCAIS!$A:$A,0)),"") -> Transbordo Registro | G13: =IFERROR(INDEX(LOCAIS!$D:$D,MATCH(TRECHOS!$G4,LOCAIS!$A:$A,0))&" - "&INDEX(LOCAIS!$E:$E,MATCH(TRECHOS!$G4,LOCAIS!$A:$A,0))&"/"&INDEX(LOCAIS!$F:$F,MATCH(TRECHOS!$G4,LOCAIS!$A:$A,0)),"") -> BR-116, km 440 - Registro/SP | H13: =TRECHOS!$H4 -> 400
A14: =IF(TRECHOS!$D5=$B$2,"SIM","-") -> - | B14: =IFERROR(INDEX(ITENS_PEDIDO!$F:$F,MATCH(TRECHOS!$B5,ITENS_PEDIDO!$A:$A,0)),"") -> Sedan 1.8 | C14: =IFERROR(INDEX(ITENS_PEDIDO!$D:$D,MATCH(TRECHOS!$B5,ITENS_PEDIDO!$A:$A,0)),"") -> JKL-4444 | D14: =TRECHOS!$B5 -> IT-004 | E14: =IFERROR(INDEX(LOCAIS!$B:$B,MATCH(TRECHOS!$F5,LOCAIS!$A:$A,0)),"") -> Pátio Beta Seminovos Campinas | F14: =IFERROR(INDEX(LOCAIS!$B:$B,MATCH(TRECHOS!$G5,LOCAIS!$A:$A,0)),"") -> Transbordo Registro | G14: =IFERROR(INDEX(LOCAIS!$D:$D,MATCH(TRECHOS!$G5,LOCAIS!$A:$A,0))&" - "&INDEX(LOCAIS!$E:$E,MATCH(TRECHOS!$G5,LOCAIS!$A:$A,0))&"/"&INDEX(LOCAIS!$F:$F,MATCH(TRECHOS!$G5,LOCAIS!$A:$A,0)),"") -> BR-116, km 440 - Registro/SP | H14: =TRECHOS!$H5 -> 400
A15: =IF(TRECHOS!$D6=$B$2,"SIM","-") -> - | B15: =IFERROR(INDEX(ITENS_PEDIDO!$F:$F,MATCH(TRECHOS!$B6,ITENS_PEDIDO!$A:$A,0)),"") -> SUV Compacto | C15: =IFERROR(INDEX(ITENS_PEDIDO!$D:$D,MATCH(TRECHOS!$B6,ITENS_PEDIDO!$A:$A,0)),"") -> MNO-5555 | D15: =TRECHOS!$B6 -> IT-005 | E15: =IFERROR(INDEX(LOCAIS!$B:$B,MATCH(TRECHOS!$F6,LOCAIS!$A:$A,0)),"") -> Pátio Beta Seminovos Campinas | F15: =IFERROR(INDEX(LOCAIS!$B:$B,MATCH(TRECHOS!$G6,LOCAIS!$A:$A,0)),"") -> Transbordo Registro | G15: =IFERROR(INDEX(LOCAIS!$D:$D,MATCH(TRECHOS!$G6,LOCAIS!$A:$A,0))&" - "&INDEX(LOCAIS!$E:$E,MATCH(TRECHOS!$G6,LOCAIS!$A:$A,0))&"/"&INDEX(LOCAIS!$F:$F,MATCH(TRECHOS!$G6,LOCAIS!$A:$A,0)),"") -> BR-116, km 440 - Registro/SP | H15: =TRECHOS!$H6 -> 400
A16: =IF(TRECHOS!$D7=$B$2,"SIM","-") -> - | B16: =IFERROR(INDEX(ITENS_PEDIDO!$F:$F,MATCH(TRECHOS!$B7,ITENS_PEDIDO!$A:$A,0)),"") -> Picape 2.8 | C16: =IFERROR(INDEX(ITENS_PEDIDO!$D:$D,MATCH(TRECHOS!$B7,ITENS_PEDIDO!$A:$A,0)),"") -> PQR-6666 | D16: =TRECHOS!$B7 -> IT-006 | E16: =IFERROR(INDEX(LOCAIS!$B:$B,MATCH(TRECHOS!$F7,LOCAIS!$A:$A,0)),"") -> Pátio Beta Seminovos Campinas | F16: =IFERROR(INDEX(LOCAIS!$B:$B,MATCH(TRECHOS!$G7,LOCAIS!$A:$A,0)),"") -> Transbordo Registro | G16: =IFERROR(INDEX(LOCAIS!$D:$D,MATCH(TRECHOS!$G7,LOCAIS!$A:$A,0))&" - "&INDEX(LOCAIS!$E:$E,MATCH(TRECHOS!$G7,LOCAIS!$A:$A,0))&"/"&INDEX(LOCAIS!$F:$F,MATCH(TRECHOS!$G7,LOCAIS!$A:$A,0)),"") -> BR-116, km 440 - Registro/SP | H16: =TRECHOS!$H7 -> 400
